Workbook

Sheet Original
I1: Training | O1: Team Structure | R1: AIM Baselines | AB1: Backlog Management | AH1: Process / Tools Standardization | AK1: Engineering Practices | AS1: Customer Management | BD1: Score Snapshots
A2: Rank | B2: Team Name | C2: Product | D2: Component | E2: Location | F2: Current Score | G2: Average Score | H2: Badge | I2: AIM Workshop (Teams) | J2: AIM Workshop (PLT) | K2: Certification - Leadership | L2: Certification – PO | M2: Certification – SM | N2: Multi Component team | O2: Product Owner | P2: Scrum Master | Q2: Multi Functional Team | R2: DoD | S2: DoR | T2: AIM ceremonies | U2: Scrum area | V2: Story Points | W2: Tasking | X2: Backlog grooming (sprint) | Y2: Backlog grooming (release) | Z2: Demo | AA2: Retro | AB2: Unified backlog | AC2: Personas | AD2: Story mapping | AE2: Work-Item templates | AF2: Tech debt strategy | AG2: Defect management strategy | AH2: AIM JIRA structure | AI2: Release tracker | AJ2: Sprint burndown | AK2: BDD | AL2: TDD | AM2: Test automation | AN2: CI/CD | AO2: Shift-left adoption | AP2: Single branch strategy | AQ2: Reducing WIP | AR2: Engineering 360 | AS2: Customer engagement | AT2: Time to Value Delivery | AU2: AIM Coach | AV2: SM | AW2: PO | AX2: Eng Manager | AY2: PLM | AZ2: Eng Sponsor (Director) | BA2: Reviewed by ACT | BB2: Start Date | BC2: AIM Age (month) | BD2: 2019 Nov (change) | BE2: 2019 Dec (change) | BF2: 2020 Jan | BG2: 2020 Feb | BH2: 2020 Mar | BI2: Progress (Points) | BJ2: Progress (%)
A3: =ROW()-2 -> 1 | B3: WeView | C3: IX Meetings | D3: Management | E3: Israel | F3: =IF(SUM(O3:AT3)>0,SUM(O3:AT3)+100,0) -> 174 | G3: =IFERROR(SUM(O3:AT3)/COUNTA(O3:AT3), "") -> 2.3125 | H3: =IF(G3>=2.8,"Legendary",IF(G3>=2,"Avenger",IF(G3>=1,"Superhero","Hero"))) -> Avenger | I3: Yes | J3: Partially | K3: Yes | L3: No | M3: Yes | N3: No | O3: 3 | P3: 3 | Q3: 3 | R3: 3 | S3: 3 | T3: 3 | U3: 3 | V3: 3 | W3: 3 | X3: 3 | Y3: 2 | Z3: 3 | AA3: 3 | AB3: 3 | AC3: 1 | AD3: 3 | AE3: 1 | AF3: 1 | AG3: 3 | AH3: 3 | AI3: 3 | AJ3: 3 | AK3: 0 | AL3: 0 | AM3: 1 | AN3: 1 | AO3: 3 | AP3: 3 | AQ3: 3 | AR3: 2 | AS3: 0 | AT3: 2 | AU3: Erez Morabia | AV3: Yafit Levi | AW3: Gilad Levi | AX3: Erez Morabia | AY3: Kirk Jones | AZ3: Danny Levi | BA3: Done | BB3: 43374 | BC3: =IF(ISBLANK($BB3),"",(TODAY()-$BB3)/30) -> 19.066667 | BD3: 161 | BE3: 160 | BF3: 158 | BG3: 164 | BH3: 162 | BI3: =F3-BF3 -> 16 | BJ3: =(F3-BF3)/BF3 -> 0.10126582
A4: =ROW()-2 -> 2 | B4: Puffin | C4: IX OneSpace | D4: - | E4: Israel | F4: =IF(SUM(O4:AT4)>0,SUM(O4:AT4)+100,0) -> 165 | G4: =IFERROR(SUM(O4:AT4)/COUNTA(O4:AT4), "") -> 2.03125 | H4: =IF(G4>=2.8,"Legendary",IF(G4>=2,"Avenger",IF(G4>=1,"Superhero","Hero"))) -> Avenger | I4: Yes | J4: Yes | K4: Yes | L4: No | M4: Yes | N4: Yes | O4: 3 | P4: 3 | Q4: 2 | R4: 1 | S4: 3 | T4: 3 | U4: 3 | V4: 3 | W4: 3 | X4: 3 | Y4: 1 | Z4: 3 | AA4: 3 | AB4: 3 | AC4: 1 | AD4: 1 | AE4: 1 | AF4: 1 | AG4: 3 | AH4: 3 | AI4: 3 | AJ4: 3 | AK4: 0 | AL4: 0 | AM4: 0 | AN4: 0 | AO4: 1 | AP4: 3 | AQ4: 2 | AR4: 2 | AS4: 2 | AT4: 2 | AU4: Erez Morabia | AV4: Dikla Klein | AW4: Tamar Goldschmidt | AX4: Erez Morabia | AY4: Orly Shechtman | AZ4: Danny Levi | BA4: Done | BB4: 43556 | BC4: =IF(ISBLANK($BB4),"",(TODAY()-$BB4)/30) -> 13 | BD4: 149 | BE4: 153 | BF4: 148 | BG4: 156 | BH4: 158 | BI4: =F4-BF4 -> 17 | BJ4: =(F4-BF4)/BF4 -> 0.11486486
A5: =ROW()-2 -> 3 | B5: Avengers | C5: IX Workplace Client | D5: Clients & CSDK | E5: India | F5: =IF(SUM(O5:AT5)>0,SUM(O5:AT5)+100,0) -> 162 | G5: =IFERROR(SUM(O5:AT5)/COUNTA(O5:AT5), "") -> 1.9375 | H5: =IF(G5>=2.8,"Legendary",IF(G5>=2,"Avenger",IF(G5>=1,"Superhero","Hero"))) -> Superhero | I5: Yes | J5: Yes | K5: No | L5: No | M5: Yes | N5: Yes | O5: 1 | P5: 1 | Q5: 3 | R5: 3 | S5: 3 | T5: 3 | U5: 3 | V5: 3 | W5: 3 | X5: 3 | Y5: 1 | Z5: 3 | AA5: 3 | AB5: 3 | AC5: 0 | AD5: 0 | AE5: 3 | AF5: 1 | AG5: 3 | AH5: 3 | AI5: 3 | AJ5: 2 | AK5: 0 | AL5: 0 | AM5: 1 | AN5: 2 | AO5: 0 | AP5: 1 | AQ5: 2 | AR5: 3 | AS5: 1 | AT5: 1 | AU5: Vijay Bholwani | AV5: Snehal Kerhalkar | AW5: Chaitanya Tilwankar & Sameer Gengane | AX5: Medha Mahabaleshwar | AY5: Paul Relf | AZ5: Ruby Agarwal | BA5: Done | BB5: 43266 | BC5: =IF(ISBLANK($BB5),"",(TODAY()-$BB5)/30) -> 22.666667 | BD5: 145 | BE5: 168 | BF5: 159 | BG5: 159 | BH5: 159 | BI5: =F5-BF5 -> 3 | BJ5: =(F5-BF5)/BF5 -> 0.018867925
A6: =ROW()-2 -> 4 | B6: Strikers | C6: IX Workplace Client | D6: Clients & CSDK | E6: India | F6: =IF(SUM(O6:AT6)>0,SUM(O6:AT6)+100,0) -> 162 | G6: =IFERROR(SUM(O6:AT6)/COUNTA(O6:AT6), "") -> 1.9375 | H6: =IF(G6>=2.8,"Legendary",IF(G6>=2,"Avenger",IF(G6>=1,"Superhero","Hero"))) -> Superhero | I6: Yes | J6: Yes | K6: No | L6: No | M6: Yes | N6: Yes | O6: 1 | P6: 1 | Q6: 3 | R6: 3 | S6: 3 | T6: 3 | U6: 3 | V6: 3 | W6: 3 | X6: 3 | Y6: 1 | Z6: 3 | AA6: 3 | AB6: 3 | AC6: 0 | AD6: 0 | AE6: 3 | AF6: 1 | AG6: 3 | AH6: 3 | AI6: 3 | AJ6: 2 | AK6: 0 | AL6: 0 | AM6: 1 | AN6: 2 | AO6: 0 | AP6: 1 | AQ6: 2 | AR6: 3 | AS6: 1 | AT6: 1 | AU6: Vijay Bholwani | AV6: Snehal Kerhalkar | AW6: Chaitanya Tilwankar & Sameer Gengane | AX6: Medha Mahabaleshwar | AY6: Paul Relf | AZ6: Ruby Agarwal | BA6: Done | BB6: 43266 | BC6: =IF(ISBLANK($BB6),"",(TODAY()-$BB6)/30) -> 22.666667 | BD6: 143 | BE6: 168 | BF6: 159 | BG6: 159 | BH6: 159 | BI6: =F6-BF6 -> 3 | BJ6: =(F6-BF6)/BF6 -> 0.018867925
A7: =ROW()-2 -> 5 | B7: ACM | C7: ACM | D7: ACM | E7: India | F7: =IF(SUM(O7:AT7)>0,SUM(O7:AT7)+100,0) -> 156 | G7: =IFERROR(SUM(O7:AT7)/COUNTA(O7:AT7), "") -> 1.75 | H7: =IF(G7>=2.8,"Legendary",IF(G7>=2,"Avenger",IF(G7>=1,"Superhero","Hero"))) -> Superhero | I7: Yes | J7: Yes | K7: No | L7: Yes | M7: No | N7: No | O7: 2 | P7: 2 | Q7: 1 | R7: 2 | S7: 3 | T7: 3 | U7: 3 | V7: 3 | W7: 3 | X7: 1 | Y7: 1 | Z7: 3 | AA7: 3 | AB7: 3 | AC7: 1 | AD7: 1 | AE7: 3 | AF7: 1 | AG7: 3 | AH7: 3 | AI7: 3 | AJ7: 1 | AK7: 0 | AL7: 0 | AM7: 1 | AN7: 1 | AO7: 1 | AP7: 1 | AQ7: 1 | AR7: 1 | AS7: 1 | AT7: 0 | AU7: Vijay Bholwani | AV7: Avinash Shendage | AW7: Ankur Rajan Verma | AY7: Joyce F | AZ7: Sanjog Kotnis | BA7: Done | BB7: 43466 | BC7: =IF(ISBLANK($BB7),"",(TODAY()-$BB7)/30) -> 16 | BD7: 171 | BE7: 161 | BF7: 154 | BG7: 154 | BH7: 154 | BI7: =F7-BF7 -> 2 | BJ7: =(F7-BF7)/BF7 -> 0.012987013
A8: =ROW()-2 -> 6 | B8: Grasshopper | C8: IX-CC | D8: Automated Services | E8: Russia | F8: =IF(SUM(O8:AT8)>0,SUM(O8:AT8)+100,0) -> 155 | G8: =IFERROR(SUM(O8:AT8)/COUNTA(O8:AT8), "") -> 1.71875 | H8: =IF(G8>=2.8,"Legendary",IF(G8>=2,"Avenger",IF(G8>=1,"Superhero","Hero"))) -> Superhero | I8: No | J8: Partially | K8: No | L8: No | M8: Yes | N8: Yes | O8: 2 | P8: 2 | Q8: 2 | R8: 2 | S8: 2 | T8: 2 | U8: 3 | V8: 2 | W8: 3 | X8: 1 | Y8: 0 | Z8: 3 | AA8: 2 | AB8: 2 | AC8: 1 | AD8: 0 | AE8: 1 | AF8: 0 | AG8: 2 | AH8: 3 | AI8: 3 | AJ8: 2 | AK8: 1 | AL8: 1 | AM8: 3 | AN8: 2 | AO8: 1 | AP8: 3 | AQ8: 1 | AR8: 2 | AS8: 1 | AT8: 0 | AU8: Shane Gannon/Sue Keegan | AV8: Alex Voron | AW8: Diego Vivo | AX8: Paul D'Arcy | AY8: Diego Klajner | AZ8: Paul D'Arcy | BA8: Done | BB8: 43481 | BC8: =IF(ISBLANK($BB8),"",(TODAY()-$BB8)/30) -> 15.5 | BD8: 103 | BE8: 160 | BF8: 153 | BG8: 153 | BH8: 153 | BI8: =F8-BF8 -> 2 | BJ8: =(F8-BF8)/BF8 -> 0.013071895
A9: =ROW()-2 -> 7 | B9: Customer Journey | C9: IX-CC | D9: Customer Journey | E9: Galway | F9: =IF(SUM(O9:AT9)>0,SUM(O9:AT9)+100,0) -> 153 | G9: =IFERROR(SUM(O9:AT9)/COUNTA(O9:AT9), "") -> 1.65625 | H9: =IF(G9>=2.8,"Legendary",IF(G9>=2,"Avenger",IF(G9>=1,"Superhero","Hero"))) -> Superhero | I9: Yes | J9: Yes | K9: No | L9: No | M9: Yes | N9: No | O9: 1 | P9: 3 | Q9: 0 | R9: 3 | S9: 3 | T9: 3 | U9: 3 | V9: 2 | W9: 2 | X9: 1 | Y9: 0 | Z9: 2 | AA9: 3 | AB9: 2 | AC9: 0 | AD9: 0 | AE9: 0 | AF9: 2 | AG9: 2 | AH9: 3 | AI9: 1 | AJ9: 2 | AK9: 0 | AL9: 0 | AM9: 3 | AN9: 2 | AO9: 0 | AP9: 3 | AQ9: 3 | AR9: 2 | AS9: 2 | AT9: 0 | AU9: Shane Gannon/Sue Keegan | AV9: Niall Fallon | AW9: Daniel O'Beirne (P) | AX9: Daniel O'Beirne | AY9: Anjali Bagora | AZ9: Paul D'Arcy | BA9: Done | BB9: 43481 | BC9: =IF(ISBLANK($BB9),"",(TODAY()-$BB9)/30) -> 15.5 | BD9: 181 | BE9: 152 | BF9: 153 | BG9: 153 | BH9: 153 | BI9: =F9-BF9 -> 0 | BJ9: =(F9-BF9)/BF9 -> 0
A10: =ROW()-2 -> 8 | B10: Pancakes | C10: Survey Assist | D10: - | E10: Argentina | F10: =IF(SUM(O10:AT10)>0,SUM(O10:AT10)+100,0) -> 152 | G10: =IFERROR(SUM(O10:AT10)/COUNTA(O10:AT10), "") -> 1.625 | H10: =IF(G10>=2.8,"Legendary",IF(G10>=2,"Avenger",IF(G10>=1,"Superhero","Hero"))) -> Superhero | I10: No | J10: No | K10: No | L10: Yes | M10: Yes | N10: Yes | O10: 1 | P10: 3 | Q10: 2 | R10: 3 | S10: 3 | T10: 2 | U10: 0 | V10: 2 | W10: 2 | X10: 1 | Y10: 0 | Z10: 3 | AA10: 3 | AB10: 3 | AC10: 1 | AD10: 1 | AE10: 1 | AF10: 1 | AG10: 1 | AH10: 3 | AI10: 3 | AJ10: 3 | AK10: 0 | AL10: 0 | AM10: 1 | AN10: 1 | AO10: 2 | AP10: 2 | AQ10: 0 | AR10: 2 | AS10: 0 | AT10: 2 | AU10: Matias Monguillot/Erez Morabia | AV10: Matias Monguillot | AW10: Marcos Vergani (P) | AX10: Marcos Vergani | AY10: Diego Klajner | AZ10: Susana Martins | BA10: Done | BB10: 43594 | BC10: =IF(ISBLANK($BB10),"",(TODAY()-$BB10)/30) -> 11.733333 | BD10: 150 | BE10: 149 | BF10: 144 | BG10: 150 | BH10: 150 | BI10: =F10-BF10 -> 8 | BJ10: =(F10-BF10)/BF10 -> 0.055555556
A11: =ROW()-2 -> 9 | B11: V8 | C11: IX Workplace Client | D11: CSDK, Windows Client App | E11: United States | F11: =IF(SUM(O11:AT11)>0,SUM(O11:AT11)+100,0) -> 151 | G11: =IFERROR(SUM(O11:AT11)/COUNTA(O11:AT11), "") -> 1.59375 | H11: =IF(G11>=2.8,"Legendary",IF(G11>=2,"Avenger",IF(G11>=1,"Superhero","Hero"))) -> Superhero | I11: Yes | J11: No | K11: No | L11: No | M11: No | N11: No | O11: 1 | P11: 2 | Q11: 1 | R11: 3 | S11: 2 | T11: 3 | U11: 3 | V11: 2 | W11: 3 | X11: 2 | Y11: 1 | Z11: 3 | AA11: 3 | AB11: 1 | AC11: 1 | AD11: 1 | AE11: 1 | AF11: 2 | AG11: 2 | AH11: 3 | AI11: 1 | AJ11: 2 | AK11: 0 | AL11: 0 | AM11: 2 | AN11: 1 | AO11: 2 | AP11: 1 | AQ11: 0 | AR11: 1 | AS11: 0 | AT11: 1 | AU11: Eric Fleischmann | AV11: Phu-Cuong Huu (Charles) Nguyen | AW11: Jeff Middleton | AX11: Marc Saunders | AY11: Paul Relf | AZ11: Ruby Agarwal | BA11: Done | BB11: 43266 | BC11: =IF(ISBLANK($BB11),"",(TODAY()-$BB11)/30) -> 22.666667 | BD11: 143 | BE11: 154 | BF11: 150 | BG11: 150 | BH11: 150 | BI11: =F11-BF11 -> 1 | BJ11: =(F11-BF11)/BF11 -> 0.0066666667
A12: =ROW()-2 -> 10 | B12: Pole Dancers | C12: ACI | D12: ACI Core, Cloud Services, ML | E12: Poland | F12: =IF(SUM(O12:AT12)>0,SUM(O12:AT12)+100,0) -> 150 | G12: =IFERROR(SUM(O12:AT12)/COUNTA(O12:AT12), "") -> 1.5625 | H12: =IF(G12>=2.8,"Legendary",IF(G12>=2,"Avenger",IF(G12>=1,"Superhero","Hero"))) -> Superhero | I12: No | J12: No | K12: No | L12: Yes | M12: No | N12: Yes | O12: 1 | P12: 2 | Q12: 3 | R12: 3 | S12: 2 | T12: 2 | U12: 3 | V12: 2 | W12: 3 | X12: 2 | Y12: 1 | Z12: 2 | AA12: 2 | AB12: 2 | AC12: 1 | AD12: 1 | AE12: 0 | AF12: 1 | AG12: 0 | AH12: 3 | AI12: 1 | AJ12: 2 | AK12: 0 | AL12: 0 | AM12: 2 | AN12: 2 | AO12: 1 | AP12: 2 | AQ12: 1 | AR12: 0 | AS12: 2 | AT12: 1 | AU12: Eric Fleischmann | AV12: Lukasz Wojciak | AW12: Michael Salen | AX12: Lukasz Wojciak | AY12: Ernie Wong | AZ12: Jeff Hodson | BA12: Done | BB12: 43626 | BC12: =IF(ISBLANK($BB12),"",(TODAY()-$BB12)/30) -> 10.666667 | BD12: 131 | BE12: 152 | BF12: 146 | BG12: 147 | BH12: 147 | BI12: =F12-BF12 -> 4 | BJ12: =(F12-BF12)/BF12 -> 0.02739726
A13: =ROW()-2 -> 11 | B13: DES | C13: DES | E13: India | F13: =IF(SUM(O13:AT13)>0,SUM(O13:AT13)+100,0) -> 149 | G13: =IFERROR(SUM(O13:AT13)/COUNTA(O13:AT13), "") -> 1.53125 | H13: =IF(G13>=2.8,"Legendary",IF(G13>=2,"Avenger",IF(G13>=1,"Superhero","Hero"))) -> Superhero | I13: Yes | J13: Yes | K13: No | L13: Yes | M13: Yes | N13: No | O13: 1 | P13: 1 | Q13: 1 | R13: 3 | S13: 3 | T13: 2 | U13: 2 | V13: 2 | W13: 2 | X13: 1 | Y13: 3 | Z13: 3 | AA13: 3 | AB13: 1 | AC13: 1 | AD13: 1 | AE13: 1 | AF13: 1 | AG13: 3 | AH13: 3 | AI13: 3 | AJ13: 1 | AK13: 0 | AL13: 1 | AM13: 3 | AN13: 1 | AO13: 0 | AP13: 1 | AQ13: 0 | AR13: 0 | AS13: 1 | AT13: 0 | AU13: Vijay Bholwani | AV13: Surabhi Misra | AY13: Bob Fizzard | AZ13: Birendra Sinha | BA13: Done | BB13: 43466 | BC13: =IF(ISBLANK($BB13),"",(TODAY()-$BB13)/30) -> 16 | BD13: 154 | BE13: 151 | BF13: 148 | BG13: 148 | BH13: 148 | BI13: =F13-BF13 -> 1 | BJ13: =(F13-BF13)/BF13 -> 0.0067567568
A14: =ROW()-2 -> 12 | B14: Kraken | C14: J SERIES | D14: RingCentral ACO/RCO features | E14: Canada | F14: =IF(SUM(O14:AT14)>0,SUM(O14:AT14)+100,0) -> 149 | G14: =IFERROR(SUM(O14:AT14)/COUNTA(O14:AT14), "") -> 1.53125 | H14: =IF(G14>=2.8,"Legendary",IF(G14>=2,"Avenger",IF(G14>=1,"Superhero","Hero"))) -> Superhero | I14: Yes | J14: Yes | K14: No | L14: No | M14: Yes | N14: Yes | O14: 1 | P14: 2 | Q14: 1 | R14: 2 | S14: 2 | T14: 2 | U14: 2 | V14: 2 | W14: 2 | X14: 2 | Y14: 1 | Z14: 3 | AA14: 3 | AB14: 0 | AC14: 2 | AD14: 2 | AE14: 1 | AF14: 1 | AG14: 1 | AH14: 3 | AI14: 1 | AJ14: 3 | AK14: 1 | AL14: 0 | AM14: 2 | AN14: 1 | AO14: 2 | AP14: 2 | AQ14: 1 | AR14: 0 | AS14: 1 | AT14: 0 | AU14: Eric Fleischmann | AV14: Shahid Mahmood | AW14: Shahid Mahmood, Xuejun (Steven) Xu | AX14: James Erskine | AY14: Bob Fizzard | AZ14: Jarek Kovak | BA14: Done | BB14: 43586 | BC14: =IF(ISBLANK($BB14),"",(TODAY()-$BB14)/30) -> 12 | BD14: 128 | BE14: 146 | BF14: 144 | BG14: 144 | BH14: 147 | BI14: =F14-BF14 -> 5 | BJ14: =(F14-BF14)/BF14 -> 0.034722222
A15: =ROW()-2 -> 13 | B15: Sherlocks | C15: IX-CC | D15: NGM | E15: India | F15: =IF(SUM(O15:AT15)>0,SUM(O15:AT15)+100,0) -> 148 | G15: =IFERROR(SUM(O15:AT15)/COUNTA(O15:AT15), "") -> 1.5 | H15: =IF(G15>=2.8,"Legendary",IF(G15>=2,"Avenger",IF(G15>=1,"Superhero","Hero"))) -> Superhero | I15: Yes | J15: Yes | K15: No | L15: No | M15: Yes | N15: Yes | O15: 1 | P15: 1 | Q15: 2 | R15: 2 | S15: 2 | T15: 2 | U15: 2 | V15: 2 | W15: 2 | X15: 1 | Y15: 1 | Z15: 3 | AA15: 3 | AB15: 3 | AC15: 0 | AD15: 1 | AE15: 1 | AF15: 1 | AG15: 1 | AH15: 3 | AI15: 3 | AJ15: 2 | AK15: 1 | AL15: 0 | AM15: 3 | AN15: 1 | AO15: 0 | AP15: 1 | AQ15: 0 | AR15: 3 | AS15: 0 | AT15: 0 | AU15: Vijay Bholwani | AV15: Surabhi Misra | AW15: Manoj Chaudhari | AX15: Birendra Sinha | AY15: Wayne Bevan | AZ15: Paul D'Arcy | BA15: Done | BB15: 43523 | BC15: =IF(ISBLANK($BB15),"",(TODAY()-$BB15)/30) -> 14.1 | BD15: 156 | BE15: 150 | BF15: 146 | BG15: 146 | BH15: 146 | BI15: =F15-BF15 -> 2 | BJ15: =(F15-BF15)/BF15 -> 0.01369863
A16: =ROW()-2 -> 14 | B16: Rangers | C16: IX Workplace Client | D16: Equinox Client | E16: Argentina | F16: =IF(SUM(O16:AT16)>0,SUM(O16:AT16)+100,0) -> 143 | G16: =IFERROR(SUM(O16:AT16)/COUNTA(O16:AT16), "") -> 1.34375 | H16: =IF(G16>=2.8,"Legendary",IF(G16>=2,"Avenger",IF(G16>=1,"Superhero","Hero"))) -> Superhero | I16: No | J16: No | K16: No | L16: No | M16: Yes | N16: No | O16: 1 | P16: 2 | Q16: 1 | R16: 3 | S16: 2 | T16: 3 | U16: 3 | V16: 1 | W16: 2 | X16: 2 | Y16: 1 | Z16: 3 | AA16: 2 | AB16: 2 | AC16: 0 | AD16: 0 | AE16: 0 | AF16: 0 | AG16: 1 | AH16: 3 | AI16: 1 | AJ16: 2 | AK16: 0 | AL16: 0 | AM16: 1 | AN16: 1 | AO16: 1 | AP16: 2 | AQ16: 1 | AR16: 1 | AS16: 0 | AT16: 1 | AU16: Eric Fleischmann | AV16: Matias Maccaglia | AW16: Mariano Bonatti | AX16: Mauricio Silclir | AY16: Paul Relf | AZ16: Ruby Agarwal | BA16: Done | BB16: 43266 | BC16: =IF(ISBLANK($BB16),"",(TODAY()-$BB16)/30) -> 22.666667 | BD16: 139 | BE16: 146 | BF16: 142 | BG16: 142 | BH16: 142 | BI16: =F16-BF16 -> 1 | BJ16: =(F16-BF16)/BF16 -> 0.0070422535
A17: =ROW()-2 -> 15 | B17: GameofScrums | C17: IX-CC | D17: IX Reporting/Analytics | E17: Galway | F17: =IF(SUM(O17:AT17)>0,SUM(O17:AT17)+100,0) -> 143 | G17: =IFERROR(SUM(O17:AT17)/COUNTA(O17:AT17), "") -> 1.34375 | H17: =IF(G17>=2.8,"Legendary",IF(G17>=2,"Avenger",IF(G17>=1,"Superhero","Hero"))) -> Superhero | I17: Yes | J17: Yes | K17: No | L17: No | M17: Yes | N17: No | O17: 2 | P17: 2 | Q17: 1 | R17: 2 | S17: 2 | T17: 3 | U17: 3 | V17: 1 | W17: 1 | X17: 1 | Y17: 1 | Z17: 3 | AA17: 3 | AB17: 2 | AC17: 0 | AD17: 1 | AE17: 1 | AF17: 1 | AG17: 1 | AH17: 3 | AI17: 3 | AJ17: 1 | AK17: 0 | AL17: 0 | AM17: 1 | AN17: 1 | AO17: 0 | AP17: 1 | AQ17: 0 | AR17: 2 | AS17: 0 | AT17: 0 | AU17: Shane Gannon/Sue Keegan | AV17: Trupti Kondavale | AW17: Chris Dunbar | AX17: Yash Singh | AY17: Wayne Bevan | AZ17: Paul D'Arcy | BA17: Done | BB17: 43481 | BC17: =IF(ISBLANK($BB17),"",(TODAY()-$BB17)/30) -> 15.5 | BD17: 159 | BE17: 145 | BF17: 142 | BG17: 142 | BH17: 142 | BI17: =F17-BF17 -> 1 | BJ17: =(F17-BF17)/BF17 -> 0.0070422535
A18: =ROW()-2 -> 16 | B18: ACI | C18: ACI | E18: United States | F18: =IF(SUM(O18:AT18)>0,SUM(O18:AT18)+100,0) -> 143 | G18: =IFERROR(SUM(O18:AT18)/COUNTA(O18:AT18), "") -> 1.34375 | H18: =IF(G18>=2.8,"Legendary",IF(G18>=2,"Avenger",IF(G18>=1,"Superhero","Hero"))) -> Superhero | I18: Yes | J18: Partially | K18: No | L18: Yes | M18: Yes | N18: Yes | O18: 1 | P18: 1 | Q18: 2 | R18: 2 | S18: 1 | T18: 2 | U18: 1 | V18: 2 | W18: 1 | X18: 2 | Y18: 1 | Z18: 2 | AA18: 2 | AB18: 2 | AC18: 1 | AD18: 1 | AE18: 0 | AF18: 1 | AG18: 1 | AH18: 3 | AI18: 1 | AJ18: 2 | AK18: 0 | AL18: 0 | AM18: 1 | AN18: 2 | AO18: 1 | AP18: 2 | AQ18: 2 | AR18: 0 | AS18: 2 | AT18: 1 | AU18: Eric Fleischmann | AV18: Matthew Peters | AW18: Michael Salen | AX18: Matthew Peters | AY18: Ernie Wong | AZ18: Jeff Hodson | BA18: Done | BB18: 43626 | BC18: =IF(ISBLANK($BB18),"",(TODAY()-$BB18)/30) -> 10.666667 | BD18: 144 | BE18: 144 | BF18: 139 | BG18: 139 | BH18: 141 | BI18: =F18-BF18 -> 4 | BJ18: =(F18-BF18)/BF18 -> 0.028776978
A19: =ROW()-2 -> 17 | B19: Vikings | C19: IX Workplace for S4B | D19: Microsoft Integration | E19: Argentina | F19: n | G19: =IFERROR(SUM(O19:AT19)/COUNTA(O19:AT19), "") -> 1.28125 | H19: =IF(G19>=2.8,"Legendary",IF(G19>=2,"Avenger",IF(G19>=1,"Superhero","Hero"))) -> Superhero | I19: No | J19: No | K19: No | L19: No | M19: Yes | N19: Yes | O19: 1 | P19: 1 | Q19: 2 | R19: 1 | S19: 1 | T19: 3 | U19: 2 | V19: 2 | W19: 2 | X19: 3 | Y19: 1 | Z19: 3 | AA19: 3 | AB19: 1 | AC19: 0 | AD19: 0 | AE19: 0 | AF19: 1 | AG19: 1 | AH19: 3 | AI19: 2 | AJ19: 2 | AK19: 0 | AL19: 0 | AM19: 1 | AN19: 1 | AO19: 0 | AP19: 1 | AQ19: 1 | AR19: 0 | AS19: 1 | AT19: 1 | AU19: Eric Fleischmann | AV19: Diego Cohen | AW19: Leonardo Marzo | AX19: Gunjan Kak | AY19: Barry O'Connor | AZ19: Ruby Agarwal | BA19: Done | BB19: 43723 | BC19: =IF(ISBLANK($BB19),"",(TODAY()-$BB19)/30) -> 7.4333333 | BD19: 135 | BE19: 145 | BF19: 139 | BG19: 139 | BH19: 139 | BI19: =F19-BF19 -> #VALUE! | BJ19: =(F19-BF19)/BF19 -> #VALUE!
A20: =ROW()-2 -> 18 | B20: Mendieta | C20: IX Workplace Client | D20: CSDK & Android (for Vantage) | E20: Argentina | F20: =IF(SUM(O20:AT20)>0,SUM(O20:AT20)+100,0) -> 140 | G20: =IFERROR(SUM(O20:AT20)/COUNTA(O20:AT20), "") -> 1.25 | H20: =IF(G20>=2.8,"Legendary",IF(G20>=2,"Avenger",IF(G20>=1,"Superhero","Hero"))) -> Superhero | I20: No | J20: No | K20: No | L20: No | M20: Yes | N20: No | O20: 1 | P20: 1 | Q20: 1 | R20: 2 | S20: 1 | T20: 3 | U20: 3 | V20: 1 | W20: 2 | X20: 1 | Y20: 1 | Z20: 3 | AA20: 2 | AB20: 2 | AC20: 0 | AD20: 0 | AE20: 0 | AF20: 1 | AG20: 1 | AH20: 3 | AI20: 1 | AJ20: 3 | AK20: 0 | AL20: 0 | AM20: 1 | AN20: 1 | AO20: 1 | AP20: 2 | AQ20: 1 | AR20: 1 | AS20: 0 | AT20: 0 | AU20: Eric Fleischmann | AV20: Diego Dedacek | AW20: Mariano Bonatti | AX20: Mauricio Silclir | AY20: Paul Relf | AZ20: Ruby Agarwal | BA20: Done | BB20: 43266 | BC20: =IF(ISBLANK($BB20),"",(TODAY()-$BB20)/30) -> 22.666667 | BD20: 138 | BE20: 141 | BF20: 139 | BG20: 139 | BH20: 139 | BI20: =F20-BF20 -> 1 | BJ20: =(F20-BF20)/BF20 -> 0.0071942446
A21: =ROW()-2 -> 19 | B21: POM | C21: POM | D21: POM | E21: India | F21: =IF(SUM(O21:AT21)>0,SUM(O21:AT21)+100,0) -> 139 | G21: =IFERROR(SUM(O21:AT21)/COUNTA(O21:AT21), "") -> 1.21875 | H21: =IF(G21>=2.8,"Legendary",IF(G21>=2,"Avenger",IF(G21>=1,"Superhero","Hero"))) -> Superhero | I21: Yes | J21: Yes | K21: No | L21: No | M21: No | N21: Yes | O21: 1 | P21: 1 | Q21: 3 | R21: 2 | S21: 2 | T21: 2 | U21: 3 | V21: 1 | W21: 2 | X21: 1 | Y21: 1 | Z21: 3 | AA21: 2 | AB21: 1 | AC21: 1 | AD21: 1 | AE21: 1 | AF21: 1 | AG21: 1 | AH21: 3 | AI21: 1 | AJ21: 1 | AK21: 0 | AL21: 0 | AM21: 1 | AN21: 1 | AO21: 0 | AP21: 1 | AQ21: 1 | AR21: 0 | AS21: 0 | AT21: 0 | AU21: Vijay Bholwani | AV21: Umesh Mahajan | AW21: Prasanth Jena | AX21: Harshad Apshankar | AY21: Michael Gruen | AZ21: Sanjog Kotnis | BA21: Done | BC21: =IF(ISBLANK($BB21),"",(TODAY()-$BB21)/30) | BD21: 142 | BE21: 139 | BF21: 136 | BG21: 136 | BH21: 136 | BI21: =F21-BF21 -> 3 | BJ21: =(F21-BF21)/BF21 -> 0.022058824
A22: =ROW()-2 -> 20 | B22: Condor | C22: IX Workplace Client | D22: Equinox Client | E22: Argentina | F22: =IF(SUM(O22:AT22)>0,SUM(O22:AT22)+100,0) -> 139 | G22: =IFERROR(SUM(O22:AT22)/COUNTA(O22:AT22), "") -> 1.21875 | H22: =IF(G22>=2.8,"Legendary",IF(G22>=2,"Avenger",IF(G22>=1,"Superhero","Hero"))) -> Superhero | I22: No | J22: No | K22: No | L22: No | M22: No | N22: No | O22: 1 | P22: 1 | Q22: 1 | R22: 2 | S22: 2 | T22: 3 | U22: 1 | V22: 2 | W22: 2 | X22: 1 | Y22: 1 | Z22: 3 | AA22: 2 | AB22: 2 | AC22: 0 | AD22: 0 | AE22: 0 | AF22: 0 | AG22: 1 | AH22: 3 | AI22: 1 | AJ22: 2 | AK22: 0 | AL22: 0 | AM22: 1 | AN22: 1 | AO22: 1 | AP22: 2 | AQ22: 1 | AR22: 1 | AS22: 0 | AT22: 1 | AU22: Eric Fleischmann | AV22: Luciano Marzo | AW22: Mariano Zibecchi and Mariano Bonatti | AX22: Mauricio Silclir | AY22: Paul Relf | AZ22: Ruby Agarwal | BA22: Done | BB22: 43266 | BC22: =IF(ISBLANK($BB22),"",(TODAY()-$BB22)/30) -> 22.666667 | BD22: 139 | BE22: 142 | BF22: 138 | BG22: 138 | BH22: 138 | BI22: =F22-BF22 -> 1 | BJ22: =(F22-BF22)/BF22 -> 0.0072463768
A23: =ROW()-2 -> 21 | B23: Assisted Services | C23: IX-CC | D23: Assisted Services | E23: Galway | F23: =IF(SUM(O23:AT23)>0,SUM(O23:AT23)+100,0) -> 138 | G23: =IFERROR(SUM(O23:AT23)/COUNTA(O23:AT23), "") -> 1.1875 | H23: =IF(G23>=2.8,"Legendary",IF(G23>=2,"Avenger",IF(G23>=1,"Superhero","Hero"))) -> Superhero | I23: Yes | J23: Yes | K23: No | L23: No | M23: Yes | N23: No | O23: 1 | P23: 2 | Q23: 0 | R23: 1 | S23: 2 | T23: 2 | U23: 2 | V23: 1 | W23: 1 | X23: 1 | Y23: 0 | Z23: 2 | AA23: 3 | AB23: 2 | AC23: 0 | AD23: 0 | AE23: 0 | AF23: 2 | AG23: 2 | AH23: 3 | AI23: 1 | AJ23: 1 | AK23: 0 | AL23: 0 | AM23: 3 | AN23: 2 | AO23: 0 | AP23: 1 | AQ23: 1 | AR23: 2 | AS23: 0 | AT23: 0 | AU23: Shane Gannon/Sue Keegan | AV23: Niall Fallon | AW23: Paul Kelly | AX23: Paul Kelly & Mike Walsh | AY23: Wayne Bevan | AZ23: Paul D'Arcy | BA23: Done | BB23: 43523 | BC23: =IF(ISBLANK($BB23),"",(TODAY()-$BB23)/30) -> 14.1 | BD23: 156 | BE23: 138 | BF23: 138 | BG23: 138 | BH23: 138 | BI23: =F23-BF23 -> 0 | BJ23: =(F23-BF23)/BF23 -> 0
A24: =ROW()-2 -> 22 | B24: JaguarScript | C24: IX Workplace Client | D24: JSCSDK | E24: United States | F24: =IF(SUM(O24:AT24)>0,SUM(O24:AT24)+100,0) -> 138 | G24: =IFERROR(SUM(O24:AT24)/COUNTA(O24:AT24), "") -> 1.1875 | H24: =IF(G24>=2.8,"Legendary",IF(G24>=2,"Avenger",IF(G24>=1,"Superhero","Hero"))) -> Superhero | I24: No | J24: No | K24: No | L24: No | M24: Yes | N24: No | O24: 1 | P24: 2 | Q24: 1 | R24: 3 | S24: 2 | T24: 3 | U24: 0 | V24: 1 | W24: 2 | X24: 1 | Y24: 1 | Z24: 3 | AA24: 2 | AB24: 2 | AC24: 0 | AD24: 0 | AE24: 0 | AF24: 0 | AG24: 1 | AH24: 3 | AI24: 1 | AJ24: 2 | AK24: 0 | AL24: 0 | AM24: 1 | AN24: 1 | AO24: 1 | AP24: 2 | AQ24: 1 | AR24: 1 | AS24: 0 | AT24: 0 | AU24: Eric Fleischmann | AV24: Matias Maccaglia | AW24: Jeff Middleton | AX24: Marc Saunders | AY24: Paul Relf | AZ24: Ruby Agarwal | BA24: Done | BB24: 43266 | BC24: =IF(ISBLANK($BB24),"",(TODAY()-$BB24)/30) -> 22.666667 | BD24: 139 | BE24: 140 | BF24: 137 | BG24: 137 | BH24: 137 | BI24: =F24-BF24 -> 1 | BJ24: =(F24-BF24)/BF24 -> 0.0072992701
A25: =ROW()-2 -> 23 | B25: Hakuna Matata | C25: Vantage | D25: Services | E25: Israel | F25: =IF(SUM(O25:AT25)>0,SUM(O25:AT25)+100,0) -> 138 | G25: =IFERROR(SUM(O25:AT25)/COUNTA(O25:AT25), "") -> 1.1875 | H25: =IF(G25>=2.8,"Legendary",IF(G25>=2,"Avenger",IF(G25>=1,"Superhero","Hero"))) -> Superhero | I25: Partially | J25: Partially | K25: No | L25: No | M25: Yes | N25: No | O25: 1 | P25: 1 | Q25: 2 | R25: 2 | S25: 3 | T25: 2 | U25: 2 | V25: 1 | W25: 2 | X25: 0 | Y25: 0 | Z25: 3 | AA25: 1 | AB25: 1 | AC25: 1 | AD25: 0 | AE25: 1 | AF25: 1 | AG25: 1 | AH25: 0 | AI25: 3 | AJ25: 3 | AK25: 0 | AL25: 0 | AM25: 0 | AN25: 1 | AO25: 0 | AP25: 3 | AQ25: 2 | AR25: 0 | AS25: 0 | AT25: 1 | AU25: Erez Morabia | AV25: Victoria Lutsenko | AW25: Erez Bergman | AX25: Yuval Cohen | AY25: Vandana Brar | AZ25: Jarek Kovak | BA25: Done | BB25: 43586 | BC25: =IF(ISBLANK($BB25),"",(TODAY()-$BB25)/30) -> 12 | BD25: 128 | BE25: 127 | BF25: 126 | BG25: 129 | BH25: 133 | BI25: =F25-BF25 -> 12 | BJ25: =(F25-BF25)/BF25 -> 0.095238095
A26: =ROW()-2 -> 24 | B26: Sphinx | C26: J SERIES | D26: BLA for RingCentral | E26: Russia | F26: =IF(SUM(O26:AT26)>0,SUM(O26:AT26)+100,0) -> 137 | G26: =IFERROR(SUM(O26:AT26)/COUNTA(O26:AT26), "") -> 1.15625 | H26: =IF(G26>=2.8,"Legendary",IF(G26>=2,"Avenger",IF(G26>=1,"Superhero","Hero"))) -> Superhero | I26: No | J26: No | K26: No | L26: No | M26: No | N26: Yes | O26: 1 | P26: 1 | Q26: 1 | R26: 1 | S26: 1 | T26: 2 | U26: 0 | V26: 1 | W26: 2 | X26: 2 | Y26: 1 | Z26: 2 | AA26: 2 | AB26: 0 | AC26: 2 | AD26: 2 | AE26: 1 | AF26: 1 | AG26: 1 | AH26: 3 | AI26: 1 | AJ26: 2 | AK26: 1 | AL26: 0 | AM26: 1 | AN26: 1 | AO26: 1 | AP26: 1 | AQ26: 1 | AR26: 0 | AS26: 1 | AT26: 0 | AU26: Eric Fleischmann | AV26: Elena Novikova | AW26: Elena Novikova, Oleg Guschin | AX26: James Erskine | AY26: Bob Fizzard | AZ26: Jarek Kovak | BA26: Done | BB26: 43586 | BC26: =IF(ISBLANK($BB26),"",(TODAY()-$BB26)/30) -> 12 | BD26: 126 | BE26: 139 | BF26: 137 | BG26: 137 | BH26: 136 | BI26: =F26-BF26 -> 0 | BJ26: =(F26-BF26)/BF26 -> 0
A27: =ROW()-2 -> 25 | B27: Hippogriff | C27: J SERIES | D27: BLF, Bluetooth, Audio Codecs | E27: Russia | F27: =IF(SUM(O27:AT27)>0,SUM(O27:AT27)+100,0) -> 136 | G27: =IFERROR(SUM(O27:AT27)/COUNTA(O27:AT27), "") -> 1.125 | H27: =IF(G27>=2.8,"Legendary",IF(G27>=2,"Avenger",IF(G27>=1,"Superhero","Hero"))) -> Superhero | I27: No | J27: No | K27: No | L27: No | M27: No | N27: Yes | O27: 1 | P27: 1 | Q27: 1 | R27: 1 | S27: 1 | T27: 2 | U27: 0 | V27: 1 | W27: 2 | X27: 1 | Y27: 1 | Z27: 2 | AA27: 2 | AB27: 0 | AC27: 2 | AD27: 2 | AE27: 1 | AF27: 1 | AG27: 1 | AH27: 3 | AI27: 1 | AJ27: 2 | AK27: 1 | AL27: 0 | AM27: 1 | AN27: 1 | AO27: 1 | AP27: 1 | AQ27: 1 | AR27: 0 | AS27: 1 | AT27: 0 | AU27: Eric Fleischmann | AV27: Anastasiya Loginova | AW27: Anastasiya Loginova | AX27: James Erskine | AY27: Bob Fizzard | AZ27: Jarek Kovak | BA27: Done | BB27: 43586 | BC27: =IF(ISBLANK($BB27),"",(TODAY()-$BB27)/30) -> 12 | BD27: 126 | BE27: 138 | BF27: 136 | BG27: 136 | BH27: 135 | BI27: =F27-BF27 -> 0 | BJ27: =(F27-BF27)/BF27 -> 0
A28: =ROW()-2 -> 26 | B28: Flex/CSP-Bangalore | C28: IX-CC | D28: Flex/CSP Bangalore | E28: India | F28: =IF(SUM(O28:AT28)>0,SUM(O28:AT28)+100,0) -> 135 | G28: =IFERROR(SUM(O28:AT28)/COUNTA(O28:AT28), "") -> 1.09375 | H28: =IF(G28>=2.8,"Legendary",IF(G28>=2,"Avenger",IF(G28>=1,"Superhero","Hero"))) -> Superhero | I28: No | J28: No | K28: No | L28: No | M28: No | N28: No | O28: 1 | P28: 1 | Q28: 1 | R28: 1 | S28: 2 | T28: 2 | U28: 2 | V28: 1 | W28: 2 | X28: 1 | Y28: 1 | Z28: 1 | AA28: 1 | AB28: 2 | AC28: 0 | AD28: 0 | AE28: 1 | AF28: 1 | AG28: 2 | AH28: 3 | AI28: 3 | AJ28: 1 | AK28: 1 | AL28: 0 | AM28: 1 | AN28: 1 | AO28: 0 | AP28: 1 | AQ28: 0 | AR28: 1 | AS28: 0 | AT28: 0 | AU28: Vijay Bholwani | AV28: Divya Mohan | AW28: Dhanuj Dharmarajan & Dinesh Udayakumar (Eventing) | AX28: Girish Solapur & Divya Mohan | AY28: Mike Killeen | AZ28: Paul D'Arcy | BA28: Done | BB28: 43481 | BC28: =IF(ISBLANK($BB28),"",(TODAY()-$BB28)/30) -> 15.5 | BD28: 129 | BE28: 119 | BF28: 134 | BG28: 134 | BH28: 134 | BI28: =F28-BF28 -> 1 | BJ28: =(F28-BF28)/BF28 -> 0.0074626866
A29: =ROW()-2 -> 27 | B29: Phoenix | C29: J SERIES | D29: Mercury phones | E29: Russia | F29: =IF(SUM(O29:AT29)>0,SUM(O29:AT29)+100,0) -> 135 | G29: =IFERROR(SUM(O29:AT29)/COUNTA(O29:AT29), "") -> 1.09375 | H29: =IF(G29>=2.8,"Legendary",IF(G29>=2,"Avenger",IF(G29>=1,"Superhero","Hero"))) -> Superhero | I29: No | J29: No | K29: No | L29: No | M29: No | N29: Yes | O29: 1 | P29: 1 | Q29: 1 | R29: 1 | S29: 1 | T29: 2 | U29: 0 | V29: 1 | W29: 2 | X29: 1 | Y29: 1 | Z29: 3 | AA29: 2 | AB29: 0 | AC29: 2 | AD29: 1 | AE29: 1 | AF29: 1 | AG29: 1 | AH29: 3 | AI29: 1 | AJ29: 1 | AK29: 0 | AL29: 0 | AM29: 1 | AN29: 1 | AO29: 1 | AP29: 1 | AQ29: 1 | AR29: 0 | AS29: 1 | AT29: 1 | AU29: Eric Fleischmann | AV29: Andrey Khudenkikh | AW29: Andrey Khudenkikh, Alexander Tokmakov | AX29: James Erskine | AY29: Bob Fizzard | AZ29: Jarek Kovak | BA29: Done | BB29: 43586 | BC29: =IF(ISBLANK($BB29),"",(TODAY()-$BB29)/30) -> 12 | BD29: 126 | BE29: 136 | BF29: 135 | BG29: 135 | BH29: 134 | BI29: =F29-BF29 -> 0 | BJ29: =(F29-BF29)/BF29 -> 0
A30: =ROW()-2 -> 28 | B30: Dragon | C30: J SERIES | D30: Avaya Cloud Offer (4.0.5.0) | E30: Russia | F30: =IF(SUM(O30:AT30)>0,SUM(O30:AT30)+100,0) -> 134 | G30: =IFERROR(SUM(O30:AT30)/COUNTA(O30:AT30), "") -> 1.0625 | H30: =IF(G30>=2.8,"Legendary",IF(G30>=2,"Avenger",IF(G30>=1,"Superhero","Hero"))) -> Superhero | I30: No | J30: No | K30: No | L30: No | M30: No | N30: Yes | O30: 1 | P30: 1 | Q30: 1 | R30: 1 | S30: 1 | T30: 2 | U30: 0 | V30: 1 | W30: 2 | X30: 1 | Y30: 1 | Z30: 2 | AA30: 2 | AB30: 0 | AC30: 1 | AD30: 1 | AE30: 1 | AF30: 1 | AG30: 1 | AH30: 3 | AI30: 1 | AJ30: 2 | AK30: 1 | AL30: 0 | AM30: 1 | AN30: 1 | AO30: 1 | AP30: 1 | AQ30: 1 | AR30: 0 | AS30: 1 | AT30: 0 | AU30: Eric Fleischmann | AV30: Mikhail Tagirov | AW30: Mikhail Tagirov, Aleksey Kalita | AX30: James Erskine | AY30: Bob Fizzard | AZ30: Jarek Kovak | BA30: Done | BB30: 43586 | BC30: =IF(ISBLANK($BB30),"",(TODAY()-$BB30)/30) -> 12 | BD30: 126 | BE30: 136 | BF30: 134 | BG30: 134 | BH30: 133 | BI30: =F30-BF30 -> 0 | BJ30: =(F30-BF30)/BF30 -> 0
A31: =ROW()-2 -> 29 | B31: Warriors | C31: Vantage | D31: Platform | E31: Israel | F31: =IF(SUM(O31:AT31)>0,SUM(O31:AT31)+100,0) -> 134 | G31: =IFERROR(SUM(O31:AT31)/COUNTA(O31:AT31), "") -> 1.0625 | H31: =IF(G31>=2.8,"Legendary",IF(G31>=2,"Avenger",IF(G31>=1,"Superhero","Hero"))) -> Superhero | I31: Partially | J31: Partially | K31: No | L31: No | M31: Yes | N31: No | O31: 1 | P31: 1 | Q31: 2 | R31: 1 | S31: 3 | T31: 2 | U31: 2 | V31: 1 | W31: 2 | X31: 1 | Y31: 0 | Z31: 2 | AA31: 1 | AB31: 1 | AC31: 1 | AD31: 0 | AE31: 1 | AF31: 0 | AG31: 1 | AH31: 0 | AI31: 3 | AJ31: 1 | AK31: 0 | AL31: 0 | AM31: 0 | AN31: 1 | AO31: 0 | AP31: 3 | AQ31: 2 | AR31: 0 | AS31: 0 | AT31: 1 | AU31: Erez Morabia | AV31: Alex Krichevsky | AW31: Erez Bergman | AX31: Yuval Cohen | AY31: Vandana Brar | AZ31: Jarek Kovak | BA31: Done | BB31: 43586 | BC31: =IF(ISBLANK($BB31),"",(TODAY()-$BB31)/30) -> 12 | BD31: 127 | BE31: 125 | BF31: 123 | BG31: 123 | BH31: 128 | BI31: =F31-BF31 -> 11 | BJ31: =(F31-BF31)/BF31 -> 0.089430894
A32: =ROW()-2 -> 30 | B32: Analytics 4.0 | C32: Oceana | D32: Analytics 4.0 | E32: Galway | F32: =IF(SUM(O32:AT32)>0,SUM(O32:AT32)+100,0) -> 133 | G32: =IFERROR(SUM(O32:AT32)/COUNTA(O32:AT32), "") -> 1.03125 | H32: =IF(G32>=2.8,"Legendary",IF(G32>=2,"Avenger",IF(G32>=1,"Superhero","Hero"))) -> Superhero | I32: Partially | J32: Partially | K32: No | L32: No | M32: Yes | N32: Yes | O32: 1 | P32: 2 | Q32: 2 | R32: 1 | S32: 1 | T32: 2 | U32: 3 | V32: 0 | W32: 1 | X32: 1 | Y32: 0 | Z32: 2 | AA32: 1 | AB32: 3 | AC32: 0 | AD32: 0 | AE32: 0 | AF32: 0 | AG32: 1 | AH32: 3 | AI32: 3 | AJ32: 2 | AK32: 0 | AL32: 1 | AM32: 0 | AN32: 1 | AO32: 0 | AP32: 1 | AQ32: 0 | AR32: 0 | AS32: 0 | AT32: 1 | AU32: Dejan Savic | AV32: Dejan Savic | AY32: David Mulry | AZ32: Eugene Garvin | BA32: Done | BB32: 43691 | BC32: =IF(ISBLANK($BB32),"",(TODAY()-$BB32)/30) -> 8.5 | BD32: 159 | BE32: 136 | BF32: 132 | BG32: 131 | BH32: 131 | BI32: =F32-BF32 -> 1 | BJ32: =(F32-BF32)/BF32 -> 0.0075757576
A33: =ROW()-2 -> 31 | B33: Ahaṁ Brahmāsmi | C33: IX-CC | D33: Flex/CSP Pune | E33: India | F33: =IF(SUM(O33:AT33)>0,SUM(O33:AT33)+100,0) -> 132 | G33: =IFERROR(SUM(O33:AT33)/COUNTA(O33:AT33), "") -> 1 | H33: =IF(G33>=2.8,"Legendary",IF(G33>=2,"Avenger",IF(G33>=1,"Superhero","Hero"))) -> Superhero | I33: No | J33: No | K33: No | L33: No | M33: Yes | N33: No | O33: 1 | P33: 2 | Q33: 1 | R33: 1 | S33: 2 | T33: 3 | U33: 2 | V33: 1 | W33: 2 | X33: 1 | Y33: 1 | Z33: 1 | AA33: 2 | AB33: 1 | AC33: 0 | AD33: 0 | AE33: 1 | AF33: 1 | AG33: 1 | AH33: 3 | AI33: 3 | AJ33: 1 | AK33: 0 | AL33: 0 | AM33: 0 | AN33: 1 | AO33: 0 | AP33: 0 | AQ33: 0 | AR33: 0 | AS33: 0 | AT33: 0 | AU33: Vijay Bholwani | AV33: Barkha Shukla | AW33: Shankar Makjija | AX33: Birendra Sinha & Anjali Doiphode | AY33: Mike Killeen | AZ33: Paul D'Arcy | BA33: Done | BB33: 43481 | BC33: =IF(ISBLANK($BB33),"",(TODAY()-$BB33)/30) -> 15.5 | BD33: 129 | BE33: 134 | BF33: 131 | BG33: 131 | BH33: 131 | BI33: =F33-BF33 -> 1 | BJ33: =(F33-BF33)/BF33 -> 0.0076335878
A34: =ROW()-2 -> 32 | B34: Unicorn | C34: J SERIES | D34: J189 / J189 UI components | E34: Russia | F34: =IF(SUM(O34:AT34)>0,SUM(O34:AT34)+100,0) -> 132 | G34: =IFERROR(SUM(O34:AT34)/COUNTA(O34:AT34), "") -> 1 | H34: =IF(G34>=2.8,"Legendary",IF(G34>=2,"Avenger",IF(G34>=1,"Superhero","Hero"))) -> Superhero | I34: No | J34: No | K34: No | L34: No | M34: No | N34: Yes | O34: 1 | P34: 1 | Q34: 1 | R34: 1 | S34: 1 | T34: 2 | U34: 0 | V34: 1 | W34: 1 | X34: 1 | Y34: 1 | Z34: 2 | AA34: 2 | AB34: 0 | AC34: 2 | AD34: 2 | AE34: 1 | AF34: 1 | AG34: 1 | AH34: 3 | AI34: 1 | AJ34: 1 | AK34: 0 | AL34: 0 | AM34: 1 | AN34: 1 | AO34: 1 | AP34: 0 | AQ34: 1 | AR34: 0 | AS34: 1 | AT34: 0 | AU34: Eric Fleischmann | AV34: Svetlana Podogova | AW34: Mikhail Tugashov, Svetlana Podogova | AX34: James Erskine | AY34: Bob Fizzard | AZ34: Jarek Kovak | BA34: Done | BB34: 43586 | BC34: =IF(ISBLANK($BB34),"",(TODAY()-$BB34)/30) -> 12 | BD34: 126 | BE34: 134 | BF34: 132 | BG34: 132 | BH34: 131 | BI34: =F34-BF34 -> 0 | BJ34: =(F34-BF34)/BF34 -> 0
A35: =ROW()-2 -> 33 | B35: Wyvern | C35: J SERIES | D35: LDAP, IPv6 | E35: Russia | F35: =IF(SUM(O35:AT35)>0,SUM(O35:AT35)+100,0) -> 132 | G35: =IFERROR(SUM(O35:AT35)/COUNTA(O35:AT35), "") -> 1 | H35: =IF(G35>=2.8,"Legendary",IF(G35>=2,"Avenger",IF(G35>=1,"Superhero","Hero"))) -> Superhero | I35: No | J35: No | K35: No | L35: No | M35: No | N35: Yes | O35: 1 | P35: 1 | Q35: 1 | R35: 1 | S35: 1 | T35: 2 | U35: 0 | V35: 1 | W35: 2 | X35: 1 | Y35: 1 | Z35: 2 | AA35: 2 | AB35: 0 | AC35: 1 | AD35: 1 | AE35: 1 | AF35: 1 | AG35: 1 | AH35: 3 | AI35: 1 | AJ35: 1 | AK35: 1 | AL35: 0 | AM35: 1 | AN35: 1 | AO35: 0 | AP35: 1 | AQ35: 1 | AR35: 0 | AS35: 1 | AT35: 0 | AU35: Eric Fleischmann | AV35: Alex Lyubimov | AW35: Alex Lyubimov | AX35: James Erskine | AY35: Bob Fizzard | AZ35: Jarek Kovak | BA35: Done | BB35: 43586 | BC35: =IF(ISBLANK($BB35),"",(TODAY()-$BB35)/30) -> 12 | BD35: 126 | BE35: 134 | BF35: 132 | BG35: 132 | BH35: 131 | BI35: =F35-BF35 -> 0 | BJ35: =(F35-BF35)/BF35 -> 0
A36: =ROW()-2 -> 34 | B36: Black Pearl | C36: J SERIES | D36: RTCP XR for RingCentral, Web UI | E36: India | F36: =IF(SUM(O36:AT36)>0,SUM(O36:AT36)+100,0) -> 131 | G36: =IFERROR(SUM(O36:AT36)/COUNTA(O36:AT36), "") -> 0.96875 | H36: =IF(G36>=2.8,"Legendary",IF(G36>=2,"Avenger",IF(G36>=1,"Superhero","Hero"))) -> Hero | I36: Yes | J36: Yes | K36: No | L36: No | M36: Yes | N36: Yes | O36: 1 | P36: 1 | Q36: 1 | R36: 1 | S36: 2 | T36: 2 | U36: 1 | V36: 1 | W36: 1 | X36: 0 | Y36: 1 | Z36: 3 | AA36: 1 | AB36: 1 | AC36: 1 | AD36: 1 | AE36: 1 | AF36: 1 | AG36: 1 | AH36: 3 | AI36: 1 | AJ36: 1 | AK36: 0 | AL36: 0 | AM36: 0 | AN36: 1 | AO36: 1 | AP36: 1 | AQ36: 0 | AR36: 0 | AS36: 1 | AT36: 0 | AU36: Vijay Bholwani | AV36: Gyanesh Soni | AW36: Jena Debakanta | AX36: Anand Padhye | AY36: Bob Fizzard | AZ36: Jarek Kovak | BA36: Done | BB36: 43586 | BC36: =IF(ISBLANK($BB36),"",(TODAY()-$BB36)/30) -> 12 | BD36: 120 | BE36: 129 | BF36: 128 | BG36: 128 | BH36: 130 | BI36: =F36-BF36 -> 3 | BJ36: =(F36-BF36)/BF36 -> 0.0234375
A37: =ROW()-2 -> 35 | B37: Analytics 3.x | C37: Oceana | D37: Analytics 3.x | E37: Galway | F37: =IF(SUM(O37:AT37)>0,SUM(O37:AT37)+100,0) -> 131 | G37: =IFERROR(SUM(O37:AT37)/COUNTA(O37:AT37), "") -> 0.96875 | H37: =IF(G37>=2.8,"Legendary",IF(G37>=2,"Avenger",IF(G37>=1,"Superhero","Hero"))) -> Hero | I37: Partially | J37: Yes | K37: No | L37: No | M37: Yes | N37: No | O37: 1 | P37: 2 | Q37: 1 | R37: 1 | S37: 1 | T37: 2 | U37: 3 | V37: 0 | W37: 1 | X37: 1 | Y37: 0 | Z37: 2 | AA37: 1 | AB37: 3 | AC37: 0 | AD37: 0 | AE37: 0 | AF37: 0 | AG37: 1 | AH37: 3 | AI37: 3 | AJ37: 2 | AK37: 0 | AL37: 1 | AM37: 0 | AN37: 0 | AO37: 0 | AP37: 1 | AQ37: 0 | AR37: 0 | AS37: 0 | AT37: 1 | AU37: Dejan Savic | AV37: Dejan Savic | AW37: Dejan Savic | AY37: David Mulry | AZ37: Eugene Garvin | BA37: Done | BB37: 43621 | BC37: =IF(ISBLANK($BB37),"",(TODAY()-$BB37)/30) -> 10.833333 | BD37: 156 | BE37: 136 | BF37: 131 | BG37: 130 | BH37: 130 | BI37: =F37-BF37 -> 0 | BJ37: =(F37-BF37)/BF37 -> 0
A38: =ROW()-2 -> 36 | B38: Gravity | C38: Usage Metering | D38: - | E38: India | F38: =IF(SUM(O38:AT38)>0,SUM(O38:AT38)+100,0) -> 131 | G38: =IFERROR(SUM(O38:AT38)/COUNTA(O38:AT38), "") -> 0.96875 | H38: =IF(G38>=2.8,"Legendary",IF(G38>=2,"Avenger",IF(G38>=1,"Superhero","Hero"))) -> Hero | I38: Yes | J38: Yes | K38: No | L38: No | M38: No | N38: No | O38: 1 | P38: 1 | Q38: 1 | R38: 1 | S38: 1 | T38: 2 | U38: 1 | V38: 1 | W38: 2 | X38: 1 | Y38: 1 | Z38: 3 | AA38: 2 | AB38: 2 | AC38: 0 | AD38: 1 | AE38: 1 | AF38: 1 | AG38: 2 | AH38: 0 | AI38: 1 | AJ38: 1 | AK38: 0 | AL38: 0 | AM38: 0 | AN38: 1 | AO38: 0 | AP38: 2 | AQ38: 1 | AR38: 0 | AS38: 0 | AT38: 0 | AU38: Vijay Bholwani | AV38: Sameer Sohanee | AW38: Gaurav Rachchh | AX38: Eyal Serero | AY38: Orly Shechtman | AZ38: Becky Richardson | BA38: Done | BD38: 0 | BE38: 0 | BF38: 130 | BG38: 130 | BH38: 130 | BI38: =F38-BF38 -> 1 | BJ38: =(F38-BF38)/BF38 -> 0.0076923077
A39: =ROW()-2 -> 37 | B39: Bahubali | C39: AWFOS | E39: India | F39: =IF(SUM(O39:AT39)>0,SUM(O39:AT39)+100,0) -> 131 | G39: =IFERROR(SUM(O39:AT39)/COUNTA(O39:AT39), "") -> 0.96875 | H39: =IF(G39>=2.8,"Legendary",IF(G39>=2,"Avenger",IF(G39>=1,"Superhero","Hero"))) -> Hero | I39: No | J39: Yes | K39: No | L39: No | M39: Yes | N39: Yes | O39: 1 | P39: 1 | Q39: 2 | R39: 2 | S39: 2 | T39: 2 | U39: 1 | V39: 1 | W39: 2 | X39: 1 | Y39: 1 | Z39: 1 | AA39: 1 | AB39: 1 | AC39: 1 | AD39: 1 | AE39: 1 | AF39: 1 | AG39: 1 | AH39: 3 | AI39: 1 | AJ39: 1 | AK39: 0 | AL39: 0 | AM39: 1 | AN39: 1 | AO39: 0 | AP39: 0 | AQ39: 0 | AR39: 0 | AS39: 0 | AT39: 0 | AU39: Vijay Bholwani | AV39: Guru Ayondhyanath | AY39: William Jolicoeur | AZ39: Pat Lawless | BA39: Done | BB39: 43466 | BC39: =IF(ISBLANK($BB39),"",(TODAY()-$BB39)/30) -> 16 | BD39: 138 | BE39: 133 | BF39: 129 | BG39: 129 | BH39: 129 | BI39: =F39-BF39 -> 2 | BJ39: =(F39-BF39)/BF39 -> 0.015503876
A40: =ROW()-2 -> 38 | B40: Usage Metering | C40: Usage Metering | D40: - | E40: Israel | F40: =IF(SUM(O40:AT40)>0,SUM(O40:AT40)+100,0) -> 130 | G40: =IFERROR(SUM(O40:AT40)/COUNTA(O40:AT40), "") -> 0.9375 | H40: =IF(G40>=2.8,"Legendary",IF(G40>=2,"Avenger",IF(G40>=1,"Superhero","Hero"))) -> Hero | I40: Partially | J40: Yes | K40: No | L40: No | M40: No | N40: No | O40: 1 | P40: 1 | Q40: 2 | R40: 1 | S40: 1 | T40: 1 | U40: 1 | V40: 1 | W40: 2 | X40: 0 | Y40: 0 | Z40: 2 | AA40: 2 | AB40: 2 | AC40: 0 | AD40: 1 | AE40: 0 | AF40: 0 | AG40: 0 | AH40: 3 | AI40: 3 | AJ40: 1 | AK40: 0 | AL40: 0 | AM40: 0 | AN40: 1 | AO40: 0 | AP40: 2 | AQ40: 0 | AR40: 0 | AS40: 0 | AT40: 2 | AU40: Erez Morabia | AV40: Zvika Oskar | AW40: Eyal Serero (P) | AX40: Eyal Serero | AY40: Orly Shechtman | AZ40: Becky Richardson | BA40: Done | BB40: 43586 | BC40: =IF(ISBLANK($BB40),"",(TODAY()-$BB40)/30) -> 12 | BD40: 136 | BE40: 134 | BF40: 129 | BG40: 129 | BH40: 129 | BI40: =F40-BF40 -> 1 | BJ40: =(F40-BF40)/BF40 -> 0.007751938
...

Sheet PMT
E2: Product line | F2: J SERIES
E4: Product Owner | F4: Scrum Master | G4: Multi Functional Team | H4: DoD | I4: DoR | J4: AIM ceremonies | K4: Scrum area | L4: Story Points | M4: Tasking | N4: Backlog grooming (sprint) | O4: Backlog grooming (release) | P4: Demo | Q4: Retro | R4: Unified backlog | S4: Personas | T4: Story mapping | U4: Work-Item templates | V4: Tech debt strategy | W4: Defect management strategy | X4: AIM JIRA structure | Y4: Release tracker | Z4: Sprint burndown | AA4: BDD | AB4: TDD | AC4: Test automation | AD4: CI/CD | AE4: Shift-left adoption | AF4: Single branch strategy | AG4: Reducing WIP | AH4: Engineering 360 | AI4: Customer engagement | AJ4: Time to Value Delivery
E5: =SUMPRODUCT( (Original!$O$3:$AS$101) * (Original!$C$3:$C$101 = $F$2) * (Original!$O$2:$AS$2 = E4)) / (COUNTIF(Original!$C$3:$C$101,PMT!$F$2)*3) -> 0.33333333 | F5: =SUMPRODUCT( (Original!$O$3:$AS$101) * (Original!$C$3:$C$101 = $F$2) * (Original!$O$2:$AS$2 = F4)) / (COUNTIF(Original!$C$3:$C$101,PMT!$F$2)*3) -> 0.375 | G5: =SUMPRODUCT( (Original!$O$3:$AS$101) * (Original!$C$3:$C$101 = $F$2) * (Original!$O$2:$AS$2 = G4)) / (COUNTIF(Original!$C$3:$C$101,PMT!$F$2)*3) -> 0.33333333 | H5: =SUMPRODUCT( (Original!$O$3:$AS$101) * (Original!$C$3:$C$101 = $F$2) * (Original!$O$2:$AS$2 = H4)) / (COUNTIF(Original!$C$3:$C$101,PMT!$F$2)*3) -> 0.375 | I5: =SUMPRODUCT( (Original!$O$3:$AS$101) * (Original!$C$3:$C$101 = $F$2) * (Original!$O$2:$AS$2 = I4)) / (COUNTIF(Original!$C$3:$C$101,PMT!$F$2)*3) -> 0.41666667 | J5: =SUMPRODUCT( (Original!$O$3:$AS$101) * (Original!$C$3:$C$101 = $F$2) * (Original!$O$2:$AS$2 = J4)) / (COUNTIF(Original!$C$3:$C$101,PMT!$F$2)*3) -> 0.66666667 | K5: =SUMPRODUCT( (Original!$O$3:$AS$101) * (Original!$C$3:$C$101 = $F$2) * (Original!$O$2:$AS$2 = K4)) / (COUNTIF(Original!$C$3:$C$101,PMT!$F$2)*3) -> 0.125 | L5: =SUMPRODUCT( (Original!$O$3:$AS$101) * (Original!$C$3:$C$101 = $F$2) * (Original!$O$2:$AS$2 = L4)) / (COUNTIF(Original!$C$3:$C$101,PMT!$F$2)*3) -> 0.375 | ... AJ5: =SUMPRODUCT( (Original!$O$3:$AS$101) * (Original!$C$3:$C$101 = $F$2) * (Original!$O$2:$AS$2 = AJ4)) / (COUNTIF(Original!$C$3:$C$101,PMT!$F$2)*3) -> 0

Sheet SM
D2: Team | E2: Usage Metering
D4: Product Owner | E4: Scrum Master | F4: Multi Functional Team | G4: DoD | H4: DoR
D5: =INDEX(Original!$A:$AT,MATCH(SM!$E$2,Original!$B:$B,0),MATCH(D4,Original!$2:$2,0)) -> 1 | E5: =INDEX(Original!$A:$AT,MATCH(SM!$E$2,Original!$B:$B,0),MATCH(E4,Original!$2:$2,0)) -> 1 | F5: =INDEX(Original!$A:$AT,MATCH(SM!$E$2,Original!$B:$B,0),MATCH(F4,Original!$2:$2,0)) -> 2 | G5: =INDEX(Original!$A:$AT,MATCH(SM!$E$2,Original!$B:$B,0),MATCH(G4,Original!$2:$2,0)) -> 1 | H5: =INDEX(Original!$A:$AT,MATCH(SM!$E$2,Original!$B:$B,0),MATCH(H4,Original!$2:$2,0)) -> 1
D6: =INDEX('Heat Map Reference'!$A:$E,MATCH(SM!D4,'Heat Map Reference'!$A:$A,0),D5+2) -> Just introduced (<6M) | E6: =INDEX('Heat Map Reference'!$A:$E,MATCH(SM!E4,'Heat Map Reference'!$A:$A,0),E5+2) -> Just introduced (<6M) | F6: =INDEX('Heat Map Reference'!$A:$E,MATCH(SM!F4,'Heat Map Reference'!$A:$A,0),F5+2) -> Dev + QA + DevOps teams | G6: =INDEX('Heat Map Reference'!$A:$E,MATCH(SM!G4,'Heat Map Reference'!$A:$A,0),G5+2) -> Defined DoD (or part of DoD followed always) | H6: =INDEX('Heat Map Reference'!$A:$E,MATCH(SM!H4,'Heat Map Reference'!$A:$A,0),H5+2) -> Defined DoR (or part of DoR followed always)
D8: AIM ceremonies | E8: Scrum area | F8: Story Points | G8: Tasking | H8: Backlog grooming (sprint)
D9: =INDEX(Original!$A:$AT,MATCH(SM!$E$2,Original!$B:$B,0),MATCH(D8,Original!$2:$2,0)) -> 1 | E9: =INDEX(Original!$A:$AT,MATCH(SM!$E$2,Original!$B:$B,0),MATCH(E8,Original!$2:$2,0)) -> 1 | F9: =INDEX(Original!$A:$AT,MATCH(SM!$E$2,Original!$B:$B,0),MATCH(F8,Original!$2:$2,0)) -> 1 | G9: =INDEX(Original!$A:$AT,MATCH(SM!$E$2,Original!$B:$B,0),MATCH(G8,Original!$2:$2,0)) -> 2 | H9: =INDEX(Original!$A:$AT,MATCH(SM!$E$2,Original!$B:$B,0),MATCH(H8,Original!$2:$2,0)) -> 0
D10: =INDEX('Heat Map Reference'!$A:$E,MATCH(SM!D8,'Heat Map Reference'!$A:$A,0),D9+2) -> Calendar published | E10: =INDEX('Heat Map Reference'!$A:$E,MATCH(SM!E8,'Heat Map Reference'!$A:$A,0),E9+2) -> Scrum area created | F10: =INDEX('Heat Map Reference'!$A:$E,MATCH(SM!F8,'Heat Map Reference'!$A:$A,0),F9+2) -> Started using complexity-based story points | G10: =INDEX('Heat Map Reference'!$A:$E,MATCH(SM!G8,'Heat Map Reference'!$A:$A,0),G9+2) -> Sometimes all tasks are defined on first day of sprint | H10: =INDEX('Heat Map Reference'!$A:$E,MATCH(SM!H8,'Heat Map Reference'!$A:$A,0),H9+2) -> No continuous story grooming
D12: Backlog grooming (release) | E12: Demo | F12: Retro | G12: Unified backlog | H12: Personas
D13: =INDEX(Original!$A:$AT,MATCH(SM!$E$2,Original!$B:$B,0),MATCH(D12,Original!$2:$2,0)) -> 0 | E13: =INDEX(Original!$A:$AT,MATCH(SM!$E$2,Original!$B:$B,0),MATCH(E12,Original!$2:$2,0)) -> 2 | F13: =INDEX(Original!$A:$AT,MATCH(SM!$E$2,Original!$B:$B,0),MATCH(F12,Original!$2:$2,0)) -> 2 | G13: =INDEX(Original!$A:$AT,MATCH(SM!$E$2,Original!$B:$B,0),MATCH(G12,Original!$2:$2,0)) -> 2 | H13: =INDEX(Original!$A:$AT,MATCH(SM!$E$2,Original!$B:$B,0),MATCH(H12,Original!$2:$2,0)) -> 0
D14: =INDEX('Heat Map Reference'!$A:$E,MATCH(SM!D12,'Heat Map Reference'!$A:$A,0),D13+2) -> No continuous release planning | E14: =INDEX('Heat Map Reference'!$A:$E,MATCH(SM!E12,'Heat Map Reference'!$A:$A,0),E13+2) -> Done usually OR done only for part of the stories | F14: =INDEX('Heat Map Reference'!$A:$E,MATCH(SM!F12,'Heat Map Reference'!$A:$A,0),F13+2) -> Done every sprint, but not always at least one improvement is implemented | G14: =INDEX('Heat Map Reference'!$A:$E,MATCH(SM!G12,'Heat Map Reference'!$A:$A,0),G13+2) -> Demonstrated consistent single backlog maintained over 6 sprints | H14: =INDEX('Heat Map Reference'!$A:$E,MATCH(SM!H12,'Heat Map Reference'!$A:$A,0),H13+2) -> No personas
D16: Story mapping | E16: Work-Item templates | F16: Tech debt strategy | G16: Defect management strategy | H16: AIM JIRA structure
D17: =INDEX(Original!$A:$AT,MATCH(SM!$E$2,Original!$B:$B,0),MATCH(D16,Original!$2:$2,0)) -> 1 | E17: =INDEX(Original!$A:$AT,MATCH(SM!$E$2,Original!$B:$B,0),MATCH(E16,Original!$2:$2,0)) -> 0 | F17: =INDEX(Original!$A:$AT,MATCH(SM!$E$2,Original!$B:$B,0),MATCH(F16,Original!$2:$2,0)) -> 0 | G17: =INDEX(Original!$A:$AT,MATCH(SM!$E$2,Original!$B:$B,0),MATCH(G16,Original!$2:$2,0)) -> 0 | H17: =INDEX(Original!$A:$AT,MATCH(SM!$E$2,Original!$B:$B,0),MATCH(H16,Original!$2:$2,0)) -> 3
D18: =INDEX('Heat Map Reference'!$A:$E,MATCH(SM!D16,'Heat Map Reference'!$A:$A,0),D17+2) -> Story mapping done for one release | E18: =INDEX('Heat Map Reference'!$A:$E,MATCH(SM!E16,'Heat Map Reference'!$A:$A,0),E17+2) -> AIM backlog work-item template not adopted | F18: =INDEX('Heat Map Reference'!$A:$E,MATCH(SM!F16,'Heat Map Reference'!$A:$A,0),F17+2) -> No strategy | G18: =INDEX('Heat Map Reference'!$A:$E,MATCH(SM!G16,'Heat Map Reference'!$A:$A,0),G17+2) -> No strategy | H18: =INDEX('Heat Map Reference'!$A:$E,MATCH(SM!H16,'Heat Map Reference'!$A:$A,0),H17+2) -> Adopted AIM JIRA scheme
D20: Release tracker | E20: Sprint burndown | F20: BDD | G20: TDD | H20: Test automation
D21: =INDEX(Original!$A:$AT,MATCH(SM!$E$2,Original!$B:$B,0),MATCH(D20,Original!$2:$2,0)) -> 3 | E21: =INDEX(Original!$A:$AT,MATCH(SM!$E$2,Original!$B:$B,0),MATCH(E20,Original!$2:$2,0)) -> 1 | F21: =INDEX(Original!$A:$AT,MATCH(SM!$E$2,Original!$B:$B,0),MATCH(F20,Original!$2:$2,0)) -> 0 | G21: =INDEX(Original!$A:$AT,MATCH(SM!$E$2,Original!$B:$B,0),MATCH(G20,Original!$2:$2,0)) -> 0 | H21: =INDEX(Original!$A:$AT,MATCH(SM!$E$2,Original!$B:$B,0),MATCH(H20,Original!$2:$2,0)) -> 0
D22: =INDEX('Heat Map Reference'!$A:$E,MATCH(SM!D20,'Heat Map Reference'!$A:$A,0),D21+2) -> Adopted AIM recommended release tracker | E22: =INDEX('Heat Map Reference'!$A:$E,MATCH(SM!E20,'Heat Map Reference'!$A:$A,0),E21+2) -> Started tracking story point-based burndown | F22: =INDEX('Heat Map Reference'!$A:$E,MATCH(SM!F20,'Heat Map Reference'!$A:$A,0),F21+2) -> Not practiced | G22: =INDEX('Heat Map Reference'!$A:$E,MATCH(SM!G20,'Heat Map Reference'!$A:$A,0),G21+2) -> Not practiced | H22: =INDEX('Heat Map Reference'!$A:$E,MATCH(SM!H20,'Heat Map Reference'!$A:$A,0),H21+2) -> Test automation not mandatory for doneness
D24: CI/CD | E24: Shift-left adoption | F24: Single branch strategy | G24: Reducing WIP | H24: Engineering 360
D25: =INDEX(Original!$A:$AT,MATCH(SM!$E$2,Original!$B:$B,0),MATCH(D24,Original!$2:$2,0)) -> 1 | E25: =INDEX(Original!$A:$AT,MATCH(SM!$E$2,Original!$B:$B,0),MATCH(E24,Original!$2:$2,0)) -> 0 | F25: =INDEX(Original!$A:$AT,MATCH(SM!$E$2,Original!$B:$B,0),MATCH(F24,Original!$2:$2,0)) -> 2 | G25: =INDEX(Original!$A:$AT,MATCH(SM!$E$2,Original!$B:$B,0),MATCH(G24,Original!$2:$2,0)) -> 0 | H25: =INDEX(Original!$A:$AT,MATCH(SM!$E$2,Original!$B:$B,0),MATCH(H24,Original!$2:$2,0)) -> 0
D26: =INDEX('Heat Map Reference'!$A:$E,MATCH(SM!D24,'Heat Map Reference'!$A:$A,0),D25+2) -> Basic pipeline – build, test & deploy on every check-in (or at least every night) | E26: =INDEX('Heat Map Reference'!$A:$E,MATCH(SM!E24,'Heat Map Reference'!$A:$A,0),E25+2) -> Aligned with concept but not practiced | F26: =INDEX('Heat Map Reference'!$A:$E,MATCH(SM!F24,'Heat Map Reference'!$A:$A,0),F25+2) -> Uses branch per story, merge-able to master (no dev branch) | G26: =INDEX('Heat Map Reference'!$A:$E,MATCH(SM!G24,'Heat Map Reference'!$A:$A,0),G25+2) -> Most stories are in progress on any given day of sprint | H26: =INDEX('Heat Map Reference'!$A:$E,MATCH(SM!H24,'Heat Map Reference'!$A:$A,0),H25+2) -> No engineering 360 done
D28: Customer engagement | E28: Time to Value Delivery
D29: =INDEX(Original!$A:$AT,MATCH(SM!$E$2,Original!$B:$B,0),MATCH(D28,Original!$2:$2,0)) -> 0 | E29: =INDEX(Original!$A:$AT,MATCH(SM!$E$2,Original!$B:$B,0),MATCH(E28,Original!$2:$2,0)) -> 2
D30: =INDEX('Heat Map Reference'!$A:$E,MATCH(SM!D28,'Heat Map Reference'!$A:$A,0),D29+2) -> No customer engagement strategy | E30: =INDEX('Heat Map Reference'!$A:$E,MATCH(SM!E28,'Heat Map Reference'!$A:$A,0),E29+2) -> A few customer value items are delivered earlier within a sprint

Sheet Heat Map Reference
A1: Category | B1: Hero | C1: Superhero | D1: Avenger | E1: Legendary | F1: Remarks
A2: Product Owner | B2: No product owner | C2: Just introduced (<6M) | D2: Independent but not empowered | E2: Empowered to work independently | F2: Independent: can take the right AIM decisions. (Not working in a SILO, working together as a Solution.) Empowered: allowed to take the right AM decisions
A3: Scrum Master | B3: No scrum master | C3: Just introduced (<6M) | D3: Independent but not empowered | E3: Empowered to work independently | F3: Independent: can take the right AIM decisions. (Not working in a SILO, working together as a Solution.) Empowered: allowed to take the right AM decisions
A4: Multi Functional Team | B4: Separate dev & QA teams | C4: Dev + QA teams | D4: Dev + QA + DevOps teams | E4: Dev + QA + DevOps + Doc teams | F4: Doc: documentation person is part of the sprint working with the Scrum Team (+ DoD includes documentation)
A5: DoD | B5: No DoD | C5: Defined DoD (or part of DoD followed always) | D5: DoD followed sometimes | E5: DoD followed always | F5: Defined = agreement by all the relevant stakeholders, based on the AIM baseline
A6: DoR | B6: No DoR | C6: Defined DoR (or part of DoR followed always) | D6: DoR followed sometimes | E6: DoR followed always | F6: Defined = agreement by all the relevant stakeholders, based on the AIM baseline
A7: AIM ceremonies | B7: Not Defined | C7: Calendar published | D7: Calendar followed sometimes OR calendar followed always, but some events are not conducted properly | E7: Calendar followed always and events are being done properly using the AIM guidelines | F7: Daily, Planning, Refinement, Retro, Review
A8: Scrum area | B8: Not set-up | C8: Scrum area created | D8: Scrum area used sometimes | E8: Scrum area used extensively | F8: Physical/Virtual Scrum Area for daily, information radiators (escalations, notes, sprint goal, …)
A9: Story Points | B9: Not used / Hours converted to points | C9: Started using complexity-based story points | D9: Able to demonstrate predictable velocity sometimes | E9: Demonstrates predictable velocity consistently | F9: Looking for predictability, not consistency, review the expected vs. actual in velocity chart, not story pointing defects and spikes
A10: Tasking | B10: No detailed tasking | C10: Started doing low level tasks | D10: Sometimes all tasks are defined on first day of sprint | E10: All tasks are defined on first day consistently | F10: Tasking is a high-level breakdown of a story into testable pieces (<2d). This encourages WIP-limit and daily collaboration. In case tasking is hard, consider a spike.
A11: Backlog grooming (sprint) | B11: No continuous story grooming | C11: Always grooming one sprint ahead | D11: Always grooming 2 sprints ahead | E11: Always grooming 3 sprints ahead | F11: Match DoR and sized
A12: Backlog grooming (release) | B12: No continuous release planning | C12: Always grooming one release ahead at 50% confidence | D12: Always planning one release at 50% + 1 releases at 20% | E12: Always planning one release at 50% + 2 releases at 20% | F12: The PLT/SLT Kanban board can provide a good view. Shorter releases are easier to predict.
... A20: Defect management strategy | B20: No strategy | C20: Good strategy defined | D20: Good strategy implemented consistently over 6 sprints | E20: Good strategy implemented consistently over 12 sprints | F20: Procedure for handling defects. Defining defect % reduction target for a sprint/release. Team targets red/yellow zone new content defects within the sprint.
A21: AIM JIRA structure | B21: Not adopted AIM JIRA scheme | E21: Adopted AIM JIRA scheme | F21: There are only 2 JIRA schemes at Avaya: AGSP and AIM.
A22: Release tracker | B22: No release tracking dashboard | C22: Have product specific release tracker | E22: Adopted AIM recommended release tracker | F22: Gathering AIM JIRA metrics as defined here
A23: Sprint burndown | B23: No burndown or hours-based sprint burndown | C23: Started tracking story point-based burndown | D23: Few stories getting done & accepted earlier within a sprint | E23: Stories always getting ‘done’ one after another throughout the sprint!
A24: BDD | B24: Not practiced | C24: Practiced sometimes | D24: Demonstrated incremental development using BDD consistently over 6 sprints! | E24: Demonstrated incremental development using BDD consistently over 12 sprints! | F24: Delivering a story behavior (use case slice) one after the other, according to the acceptance criteria. This category doesn’t refer to automation or Cucumber.
A25: TDD | B25: Not practiced | C25: Practiced sometimes | D25: Demonstrated TDD consistently over 6 sprints! | E25: Demonstrated TDD consistently over 12 sprints!
A26: Test automation | B26: Test automation not mandatory for doneness | C26: All new code is automated for doneness | D26: Legacy code automation strategy implemented – 90% tests automated | E26: No manual tests required! | F26: O->Y: CI/CD not only on master branch, but also on feature branch. Higher-environment is used by real users.
A27: CI/CD | B27: No CI/CD pipeline | C27: Basic pipeline – build, test & deploy on every check-in (or at least every night) | D27: Enhanced pipeline – feature branches, pull requests covered. One-click promotion to higher environments | E27: Advanced pipeline – check-in to prod, blue-green deployments
A28: Shift-left adoption | B28: Aligned with concept but not practiced | C28: Demonstrates bug count found in solution testing going down | D28: Demonstrates customer found bug count in going down | E28: Customer found bugs close to zero! | F28: Single master branch strategy (always potentially releasable).
A29: Single branch strategy | B29: Multiple code branch strategy (per-person branch) | C29: Uses branch per story, merge-able to master (or dev branch) | D29: Uses branch per story, merge-able to master (no dev branch) | E29: Uses branch per sub-task, merge-able to master (without breaking anything else) | F29: Sometimes it is not possible to integrate sub-task without breaking, but this should be the minority. Encouraging breaking stories into small ones.
A30: Reducing WIP | B30: Most stories are in progress on any given day of sprint | C30: No more than 50% stories are in progress on any given day of sprint | D30: No more than 25% stories are in progress on any given day of sprint | E30: No more than 10% stories are in progress on any given day of sprint! | F30: Using a variation of AIM engineering 360 template for review in a PLT+ forum.
A31: Engineering 360 | B31: No engineering 360 done | D31: Adopted AIM engineering 360 template and did first 360 | E31: Demonstrated engineering 360 consistently over 12 sprints | F31: Alpha/Beta fixed date milestones are not enough. Continuously show progress and get feedback from the customer. Negotiate adaptions in the plan.
A32: Customer engagement | B32: No customer engagement strategy | C32: Customer engagement strategy defined! | D32: Engaged customer consistently over 6 sprints | E32: Engaged customer consistently over 12 sprints
A33: Time to Value Delivery | B33: Customer value items are usually not delivered within single sprint | C33: Customer value items are delivered by the end of each sprint | D33: A few customer value items are delivered earlier within a sprint | E33: Customer value items are always delivered one after another throughout the sprint | F33: For component teams, collaboration is required cross-teams in order to deliver value within a sprint

Sheet Outcomes vs. Practices
A1: Outcomes based on Metrics | B1: Quality | C1: Predictability | D1: Reduced Costs | E1: Throughput | F1: Team morale | G1: Customer Satisfaction | H1: Stakeholder satisfaction | I1: Continuous Value Delivery | J1: Time to Market | K1: Culture | L1: Reduced Risk
A2: AIM Workshop (Teams) | F2: V | K2: V
A3: AIM Workshop (PLT) | F3: V | K3: V
A4: Certification - Leadership | F4: V | K4: V
A5: Certification – PO | F5: V | K5: V
A6: Certification – SM | F6: V | K6: V
A7: Multi Component team | B7: V | E7: V | F7: V | I7: V | J7: V
A8: Product Owner | E8: V | H8: V | I8: V
A9: Scrum Master | C9: V | E9: V | F9: V | K9: V
A10: DoD | B10: V | D10: V | G10: V | J10: V
A11: DoR | B11: V | C11: V | E11: V | F11: V | J11: V
A12: AIM ceremonies | C12: V | E12: V | I12: V | K12: V | L12: V
A13: Scrum area | E13: V | F13: V | K13: V
A14: Story Points | C14: V | D14: V
A15: Tasking | B15: V | C15: V | E15: V | F15: V
A16: Backlog grooming (sprint) | B16: V | C16: V | E16: V | F16: V
A17: Backlog grooming (release) | B17: V | C17: V | E17: V | F17: V
A18: Demo | D18: V | H18: V | I18: V | J18: V | L18: V
A19: Retro | B19: V | C19: V | D19: V | E19: V | F19: V | K19: V
A20: Unified backlog | C20: V | E20: V | F20: V | I20: V
A21: Personas | G21: V | H21: V | I21: V | J21: V
A22: Story mapping | G22: V | H22: V | I22: V | J22: V
A23: Work-Item templates | C23: V | E23: V | I23: V
A24: Tech debt strategy | B24: V | D24: V | E24: V | G24: V
A25: Defect management strategy | B25: V | D25: V | G25: V
A26: AIM JIRA structure | C26: V
A27: Release tracker | C27: V | E27: V | I27: V | L27: V
A28: Sprint burndown | C28: V | I28: V
A29: BDD | B29: V | I29: V | L29: V
A30: TDD | B30: V | D30: V
A31: Test automation | B31: V | D31: V | E31: V | J31: V | L31: V
A32: CI/CD | D32: V | G32: V | H32: V | J32: V | L32: V
A33: Shift-left adoption | B33: V | D33: V | G33: V | L33: V
A34: Single branch strategy | B34: V | D34: V | E34: V | L34: V
A35: Reducing WIP | C35: V | I35: V | J35: V | L35: V
A36: Engineering 360 | C36: V | H36: V | L36: V
A37: Customer engagement | G37: V | I37: V | L37: V
A38: Time to Value Delivery | I38: V
B39: =COUNTA(B2:B38) -> 14 | C39: =COUNTA(C2:C38) -> 15 | D39: =COUNTA(D2:D38) -> 11 | E39: =COUNTA(E2:E38) -> 16 | F39: =COUNTA(F2:F38) -> 14 | G39: =COUNTA(G2:G38) -> 8 | H39: =COUNTA(H2:H38) -> 6 | I39: =COUNTA(I2:I38) -> 14 | ... L39: =COUNTA(L2:L38) -> 11

Sheet Agile Methods
A1: Practices by domains | B1: Scrum | C1: Kanban | D1: XP | E1: DevOps | F1: General Agile | G1: Learning
A2: AIM Workshop (Teams) | G2: V | H2: =COUNTA(B2:G2) -> 1
A3: AIM Workshop (PLT) | G3: V | H3: =COUNTA(B3:G3) -> 1
A4: Certification - Leadership | G4: V | H4: =COUNTA(B4:G4) -> 1
A5: Certification – PO | B5: V | H5: =COUNTA(B5:G5) -> 1
A6: Certification – SM | B6: V | H6: =COUNTA(B6:G6) -> 1
