Workbook

Sheet Original
J1: Training | O1: Team Structure | S1: AIM Baselines | AC1: Backlog Management | AK1: Process / Tools Standardization | AO1: Engineering Practices | AW1: Customer Management | BF1: Score Snapshots
A2: Rank | B2: Team Name | C2: Product | D2: Component | E2: Location | F2: Reviewed by ACT | G2: Current Score | H2: Average Score | I2: Badge | J2: AIM Workshop (Teams) | K2: AIM Workshop (PLT) | L2: Certification - Leadership | M2: Certification – PO | N2: Certification – SM | O2: Product Owner | P2: Scrum Master | Q2: Multi function team | R2: Multi component team | S2: DoD | T2: DoR | U2: AIM ceremonies | V2: Scrum area | W2: Story Points | X2: Tasking | Y2: Backlog grooming (sprint) | Z2: Backlog grooming (release) | AA2: Demo | AB2: Retro | AC2: Unified backlog | AD2: Personas | AE2: Story mapping | AF2: User story template | AG2: Tech story template | AH2: Spikes template | AI2: Tech debt strategy | AJ2: Defect management strategy | AK2: AIM JIRA structure | AL2: Release tracker | AM2: Sprint burndown | AN2: Time to Value Delivery | AO2: BDD | AP2: TDD | AQ2: Test automation | AR2: CI/CD | AS2: Shift-left adoption | AT2: Single branch strategy | AU2: Reducing WIP | AV2: Engineering 360 | AW2: Customer engagement | AX2: AIM Coach | AY2: SM | AZ2: PO | BA2: Eng Manager | BB2: PLM | BC2: Eng Sponsor (Director) | BD2: Start Date | BE2: AIM Age (month) | BF2: 2019 Nov | BG2: 2019 Dec | BH2: 2020 Jan | BI2: Progress
A3: =ROW()-2 -> 1 | B3: Avengers | C3: IX Workplace Client | D3: Clients & CSDK | E3: India | F3: Done | G3: =IF(SUM(O3:AW3)>0,SUM(O3:AW3)+100,0) -> 168 | H3: =IFERROR(SUM(O3:AW3)/35, "") -> 1.9428571 | I3: =IF(H3>=2.8,"Legendary",IF(H3>=2,"Avenger",IF(H3>=1,"Superhero","Hero"))) -> Superhero | J3: Yes | K3: Yes | L3: No | M3: No | N3: Yes | O3: 1 | P3: 1 | Q3: 3 | R3: 0 | S3: 3 | T3: 3 | U3: 3 | V3: 3 | W3: 3 | X3: 3 | Y3: 3 | Z3: 1 | AA3: 3 | AB3: 3 | AC3: 3 | AD3: 0 | AE3: 0 | AF3: 3 | AG3: 3 | AH3: 3 | AI3: 1 | AJ3: 3 | AK3: 3 | AL3: 3 | AM3: 2 | AN3: 1 | AO3: 0 | AP3: 0 | AQ3: 1 | AR3: 2 | AS3: 0 | AT3: 1 | AU3: 2 | AV3: 3 | AW3: 1 | AX3: Vijay Bholwani | AY3: Snehal Kerhalkar | AZ3: Chaitanya & Sameer | BA3: Medha Mahabaleshwar | BB3: Paul Relf | BC3: Ruby Agarwal | BD3: 43266 | BE3: =IF(ISBLANK($BD3),"",(TODAY()-$BD3)/30) -> 21.033333 | BF3: 145 | BG3: 168 | BH3: 168 | BI3: =BH3-BG3 -> 0
A4: =ROW()-2 -> 2 | B4: Strikers | C4: IX Workplace Client | D4: Clients & CSDK | E4: India | F4: Done | G4: =IF(SUM(O4:AW4)>0,SUM(O4:AW4)+100,0) -> 168 | H4: =IFERROR(SUM(O4:AW4)/35, "") -> 1.9428571 | I4: =IF(H4>=2.8,"Legendary",IF(H4>=2,"Avenger",IF(H4>=1,"Superhero","Hero"))) -> Superhero | J4: Yes | K4: Yes | L4: No | M4: No | N4: Yes | O4: 1 | P4: 1 | Q4: 3 | R4: 0 | S4: 3 | T4: 3 | U4: 3 | V4: 3 | W4: 3 | X4: 3 | Y4: 3 | Z4: 1 | AA4: 3 | AB4: 3 | AC4: 3 | AD4: 0 | AE4: 0 | AF4: 3 | AG4: 3 | AH4: 3 | AI4: 1 | AJ4: 3 | AK4: 3 | AL4: 3 | AM4: 2 | AN4: 1 | AO4: 0 | AP4: 0 | AQ4: 1 | AR4: 2 | AS4: 0 | AT4: 1 | AU4: 2 | AV4: 3 | AW4: 1 | AX4: Vijay Bholwani | AY4: Snehal Kerhalkar | AZ4: Chaitanya & Sameer | BA4: Medha Mahabaleshwar | BB4: Paul Relf | BC4: Ruby Agarwal | BD4: 43266 | BE4: =IF(ISBLANK($BD4),"",(TODAY()-$BD4)/30) -> 21.033333 | BF4: 143 | BG4: 168 | BH4: 168 | BI4: =BH4-BG4 -> 0
A5: =ROW()-2 -> 3 | B5: WeView | C5: IX Meetings | D5: Management | E5: Israel | F5: Done | G5: =IF(SUM(O5:AW5)>0,SUM(O5:AW5)+100,0) -> 162 | H5: =IFERROR(SUM(O5:AW5)/35, "") -> 1.7714286 | I5: =IF(H5>=2.8,"Legendary",IF(H5>=2,"Avenger",IF(H5>=1,"Superhero","Hero"))) -> Superhero | J5: Yes | K5: Partially | L5: Yes | M5: No | N5: Yes | O5: 3 | P5: 3 | Q5: 2 | R5: 1 | S5: 2 | T5: 2 | U5: 3 | V5: 3 | W5: 3 | X5: 2 | Y5: 3 | Z5: 1 | AA5: 3 | AB5: 3 | AC5: 3 | AD5: 3 | AE5: 1 | AF5: 1 | AG5: 1 | AH5: 1 | AI5: 0 | AJ5: 3 | AK5: 0 | AL5: 3 | AM5: 2 | AN5: 2 | AO5: 0 | AP5: 0 | AQ5: 0 | AR5: 0 | AS5: 3 | AT5: 2 | AU5: 1 | AV5: 2 | AW5: 0 | AX5: Erez Morabia | AY5: Yafit Levi | AZ5: Gilad Levi | BA5: Erez Morabia | BB5: Kirk Jones | BC5: Danny Levi | BD5: 43374 | BE5: =IF(ISBLANK($BD5),"",(TODAY()-$BD5)/30) -> 17.433333 | BF5: 161 | BG5: 160 | BH5: 162 | BI5: =BH5-BG5 -> 2
A6: =ROW()-2 -> 4 | B6: ACM | C6: ACM | E6: India | F6: Done | G6: =IF(SUM(O6:AW6)>0,SUM(O6:AW6)+100,0) -> 161 | H6: =IFERROR(SUM(O6:AW6)/35, "") -> 1.7428571 | I6: =IF(H6>=2.8,"Legendary",IF(H6>=2,"Avenger",IF(H6>=1,"Superhero","Hero"))) -> Superhero | J6: Yes | K6: Yes | L6: No | M6: Yes | N6: No | O6: 2 | P6: 2 | Q6: 1 | R6: 0 | S6: 2 | T6: 3 | U6: 3 | V6: 3 | W6: 3 | X6: 3 | Y6: 1 | Z6: 1 | AA6: 3 | AB6: 3 | AC6: 3 | AD6: 1 | AE6: 1 | AF6: 3 | AG6: 3 | AH6: 3 | AI6: 1 | AJ6: 3 | AK6: 3 | AL6: 3 | AM6: 1 | AN6: 0 | AO6: 0 | AP6: 0 | AQ6: 1 | AR6: 1 | AS6: 1 | AT6: 1 | AU6: 1 | AV6: 0 | AW6: 1 | AX6: Vijay Bholwani | AY6: Avinash Shendage | BB6: Joyce F | BC6: Sanjog Kotnis | BD6: 43466 | BE6: =IF(ISBLANK($BD6),"",(TODAY()-$BD6)/30) -> 14.366667 | BF6: 171 | BG6: 161 | BH6: 161 | BI6: =BH6-BG6 -> 0
A7: =ROW()-2 -> 5 | B7: Grasshopper | C7: IX-CC | D7: Automated Services | E7: Russia | F7: Done | G7: =IF(SUM(O7:AW7)>0,SUM(O7:AW7)+100,0) -> 160 | H7: =IFERROR(SUM(O7:AW7)/35, "") -> 1.7142857 | I7: =IF(H7>=2.8,"Legendary",IF(H7>=2,"Avenger",IF(H7>=1,"Superhero","Hero"))) -> Superhero | J7: No | K7: Partially | L7: No | M7: No | N7: Yes | O7: 2 | P7: 2 | Q7: 2 | R7: 1 | S7: 2 | T7: 2 | U7: 2 | V7: 3 | W7: 2 | X7: 3 | Y7: 1 | Z7: 0 | AA7: 3 | AB7: 2 | AC7: 2 | AD7: 1 | AE7: 0 | AF7: 1 | AG7: 2 | AH7: 2 | AI7: 0 | AJ7: 2 | AK7: 3 | AL7: 3 | AM7: 2 | AN7: 0 | AO7: 1 | AP7: 1 | AQ7: 3 | AR7: 2 | AS7: 1 | AT7: 3 | AU7: 1 | AV7: 2 | AW7: 1 | AX7: Shane Gannon/Sue Keegan | AY7: Alex Voron | AZ7: Diego Vivo | BA7: Paul D'Arcy | BB7: Diego Klajner | BC7: Paul D'Arcy | BD7: 43481 | BE7: =IF(ISBLANK($BD7),"",(TODAY()-$BD7)/30) -> 13.866667 | BF7: 103 | BG7: 160 | BH7: 160 | BI7: =BH7-BG7 -> 0
A8: =ROW()-2 -> 6 | B8: V8 | C8: IX Workplace Client | D8: CSDK, Windows Client App | E8: United States | F8: Done | G8: =IF(SUM(O8:AW8)>0,SUM(O8:AW8)+100,0) -> 154 | H8: =IFERROR(SUM(O8:AW8)/35, "") -> 1.5428571 | I8: =IF(H8>=2.8,"Legendary",IF(H8>=2,"Avenger",IF(H8>=1,"Superhero","Hero"))) -> Superhero | J8: Yes | K8: No | L8: No | M8: No | N8: No | O8: 1 | P8: 2 | Q8: 1 | R8: 1 | S8: 3 | T8: 2 | U8: 3 | V8: 3 | W8: 2 | X8: 3 | Y8: 2 | Z8: 1 | AA8: 3 | AB8: 3 | AC8: 1 | AD8: 1 | AE8: 1 | AF8: 1 | AG8: 1 | AH8: 1 | AI8: 2 | AJ8: 2 | AK8: 3 | AL8: 1 | AM8: 2 | AN8: 1 | AO8: 0 | AP8: 0 | AQ8: 2 | AR8: 1 | AS8: 2 | AT8: 1 | AU8: 0 | AV8: 1 | AW8: 0 | AX8: Eric Fleischmann | AY8: Phu-Cuong Huu (Charles) Nguyen | AZ8: Jeff Middleton | BA8: Marc Saunders | BB8: Paul Relf | BC8: Ruby Agarwal | BD8: 43266 | BE8: =IF(ISBLANK($BD8),"",(TODAY()-$BD8)/30) -> 21.033333 | BF8: 143 | BG8: 154 | BH8: 154 | BI8: =BH8-BG8 -> 0
A9: =ROW()-2 -> 7 | B9: Puffin | C9: IX OneSpace | D9: - | E9: Israel | F9: Done | G9: =IF(SUM(O9:AW9)>0,SUM(O9:AW9)+100,0) -> 154 | H9: =IFERROR(SUM(O9:AW9)/35, "") -> 1.5428571 | I9: =IF(H9>=2.8,"Legendary",IF(H9>=2,"Avenger",IF(H9>=1,"Superhero","Hero"))) -> Superhero | J9: Yes | K9: Yes | L9: Yes | M9: No | N9: Yes | O9: 2 | P9: 3 | Q9: 2 | R9: 3 | S9: 1 | T9: 1 | U9: 3 | V9: 3 | W9: 2 | X9: 2 | Y9: 1 | Z9: 0 | AA9: 2 | AB9: 3 | AC9: 3 | AD9: 1 | AE9: 1 | AF9: 1 | AG9: 1 | AH9: 1 | AI9: 0 | AJ9: 3 | AK9: 3 | AL9: 3 | AM9: 2 | AN9: 2 | AO9: 0 | AP9: 0 | AQ9: 0 | AR9: 0 | AS9: 1 | AT9: 1 | AU9: 0 | AV9: 2 | AW9: 1 | AX9: Erez Morabia | AY9: Dikla Klein | AZ9: Tamar Goldschmidt | BA9: Erez Morabia | BB9: Orly Shechtman | BC9: Danny Levi | BD9: 43556 | BE9: =IF(ISBLANK($BD9),"",(TODAY()-$BD9)/30) -> 11.366667 | BF9: 149 | BG9: 153 | BH9: 154 | BI9: =BH9-BG9 -> 1
A10: =ROW()-2 -> 8 | B10: Customer Journey | C10: IX-CC | D10: Customer Journey | E10: Galway | F10: In Progress | G10: =IF(SUM(O10:AW10)>0,SUM(O10:AW10)+100,0) -> 153 | H10: =IFERROR(SUM(O10:AW10)/35, "") -> 1.5142857 | I10: =IF(H10>=2.8,"Legendary",IF(H10>=2,"Avenger",IF(H10>=1,"Superhero","Hero"))) -> Superhero | J10: Yes | K10: Yes | L10: No | M10: No | N10: Yes | O10: 1 | P10: 3 | Q10: 0 | R10: 0 | S10: 3 | T10: 3 | U10: 3 | V10: 3 | W10: 2 | X10: 2 | Y10: 1 | Z10: 0 | AA10: 2 | AB10: 3 | AC10: 2 | AD10: 0 | AE10: 0 | AF10: 0 | AG10: 0 | AH10: 0 | AI10: 2 | AJ10: 2 | AK10: 3 | AL10: 1 | AM10: 2 | AN10: 0 | AO10: 0 | AP10: 0 | AQ10: 3 | AR10: 2 | AS10: 0 | AT10: 3 | AU10: 3 | AV10: 2 | AW10: 2 | AX10: Shane Gannon/Sue Keegan | AY10: Niall Fallon | AZ10: Daniel O'Beirne (P) | BA10: Daniel O'Beirne | BB10: Anjali Bagora | BC10: Paul D'Arcy | BD10: 43481 | BE10: =IF(ISBLANK($BD10),"",(TODAY()-$BD10)/30) -> 13.866667 | BF10: 181 | BG10: 152 | BH10: 153 | BI10: =BH10-BG10 -> 1
A11: =ROW()-2 -> 9 | B11: Pole Dancers | C11: ACI | D11: ACI Core, Cloud Services, Machine Learning | E11: Poland | F11: Done | G11: =IF(SUM(O11:AW11)>0,SUM(O11:AW11)+100,0) -> 152 | H11: =IFERROR(SUM(O11:AW11)/35, "") -> 1.4857143 | I11: =IF(H11>=2.8,"Legendary",IF(H11>=2,"Avenger",IF(H11>=1,"Superhero","Hero"))) -> Superhero | J11: No | K11: No | L11: No | M11: Yes | N11: No | O11: 1 | P11: 1 | Q11: 3 | R11: 1 | S11: 3 | T11: 2 | U11: 2 | V11: 3 | W11: 2 | X11: 3 | Y11: 2 | Z11: 1 | AA11: 2 | AB11: 2 | AC11: 2 | AD11: 1 | AE11: 1 | AF11: 1 | AG11: 1 | AH11: 0 | AI11: 1 | AJ11: 0 | AK11: 3 | AL11: 1 | AM11: 2 | AN11: 1 | AO11: 0 | AP11: 0 | AQ11: 2 | AR11: 2 | AS11: 1 | AT11: 2 | AU11: 1 | AV11: 0 | AW11: 2 | AX11: Eric Fleischmann | AY11: Lukasz Wojciak | AZ11: Michael Salen | BA11: Lukasz Wojciak | BB11: Ernie Wong | BC11: Jeff Hodson | BD11: 43626 | BE11: =IF(ISBLANK($BD11),"",(TODAY()-$BD11)/30) -> 9.0333333 | BF11: 131 | BG11: 152 | BH11: 152 | BI11: =BH11-BG11 -> 0
A12: =ROW()-2 -> 10 | B12: DES | C12: DES | E12: India | F12: Done | G12: =IF(SUM(O12:AW12)>0,SUM(O12:AW12)+100,0) -> 151 | H12: =IFERROR(SUM(O12:AW12)/35, "") -> 1.4571429 | I12: =IF(H12>=2.8,"Legendary",IF(H12>=2,"Avenger",IF(H12>=1,"Superhero","Hero"))) -> Superhero | J12: Yes | K12: Yes | L12: No | M12: Yes | N12: Yes | O12: 1 | P12: 1 | Q12: 1 | R12: 0 | S12: 3 | T12: 3 | U12: 2 | V12: 2 | W12: 2 | X12: 2 | Y12: 1 | Z12: 3 | AA12: 3 | AB12: 3 | AC12: 1 | AD12: 1 | AE12: 1 | AF12: 1 | AG12: 1 | AH12: 1 | AI12: 1 | AJ12: 3 | AK12: 3 | AL12: 3 | AM12: 1 | AN12: 0 | AO12: 0 | AP12: 1 | AQ12: 3 | AR12: 1 | AS12: 0 | AT12: 1 | AU12: 0 | AV12: 0 | AW12: 1 | AX12: Vijay Bholwani | AY12: Surabhi Misra | BB12: Bob Fizzard | BC12: Birendra Sinha | BD12: 43466 | BE12: =IF(ISBLANK($BD12),"",(TODAY()-$BD12)/30) -> 14.366667 | BF12: 154 | BG12: 151 | BH12: 151 | BI12: =BH12-BG12 -> 0
A13: =ROW()-2 -> 11 | B13: Sherlocks | C13: IX-CC | D13: NGM | E13: India | F13: Done | G13: =IF(SUM(O13:AW13)>0,SUM(O13:AW13)+100,0) -> 150 | H13: =IFERROR(SUM(O13:AW13)/35, "") -> 1.4285714 | I13: =IF(H13>=2.8,"Legendary",IF(H13>=2,"Avenger",IF(H13>=1,"Superhero","Hero"))) -> Superhero | J13: Yes | K13: Yes | L13: No | M13: No | N13: Yes | O13: 1 | P13: 1 | Q13: 2 | R13: 0 | S13: 2 | T13: 2 | U13: 2 | V13: 2 | W13: 2 | X13: 2 | Y13: 1 | Z13: 1 | AA13: 3 | AB13: 3 | AC13: 3 | AD13: 0 | AE13: 1 | AF13: 1 | AG13: 1 | AH13: 1 | AI13: 1 | AJ13: 1 | AK13: 3 | AL13: 3 | AM13: 2 | AN13: 0 | AO13: 1 | AP13: 0 | AQ13: 3 | AR13: 1 | AS13: 0 | AT13: 1 | AU13: 0 | AV13: 3 | AW13: 0 | AX13: Vijay Bholwani | AY13: Surabhi Misra | AZ13: Manoj Chaudhari | BA13: Birendra Sinha | BB13: Wayne Bevan | BC13: Paul D'Arcy | BD13: 43523 | BE13: =IF(ISBLANK($BD13),"",(TODAY()-$BD13)/30) -> 12.466667 | BF13: 156 | BG13: 150 | BH13: 150 | BI13: =BH13-BG13 -> 0
A14: =ROW()-2 -> 12 | B14: Pancakes | C14: Survey Assist | D14: - | E14: Argentina | F14: Done | G14: =IF(SUM(O14:AW14)>0,SUM(O14:AW14)+100,0) -> 149 | H14: =IFERROR(SUM(O14:AW14)/35, "") -> 1.4 | I14: =IF(H14>=2.8,"Legendary",IF(H14>=2,"Avenger",IF(H14>=1,"Superhero","Hero"))) -> Superhero | J14: No | K14: No | L14: No | M14: Yes | N14: Yes | O14: 1 | P14: 3 | Q14: 2 | R14: 3 | S14: 2 | T14: 2 | U14: 2 | V14: 0 | W14: 2 | X14: 2 | Y14: 1 | Z14: 0 | AA14: 2 | AB14: 3 | AC14: 2 | AD14: 1 | AE14: 0 | AF14: 0 | AG14: 0 | AH14: 0 | AI14: 1 | AJ14: 1 | AK14: 3 | AL14: 3 | AM14: 3 | AN14: 2 | AO14: 0 | AP14: 0 | AQ14: 1 | AR14: 1 | AS14: 2 | AT14: 2 | AU14: 0 | AV14: 2 | AW14: 0 | AX14: Matias Monguillot/Erez Morabia | AY14: Matias Monguillot | AZ14: Marcos Vergani (P) | BA14: Marcos Vergani | BB14: Diego Klajner | BC14: Susana Martins | BD14: 43594 | BE14: =IF(ISBLANK($BD14),"",(TODAY()-$BD14)/30) -> 10.1 | BF14: 150 | BG14: 149 | BH14: 149 | BI14: =BH14-BG14 -> 0
A15: =ROW()-2 -> 13 | B15: Kraken | C15: J SERIES | D15: RingCentral ACO/RCO features | E15: Canada | F15: Done | G15: =IF(SUM(O15:AW15)>0,SUM(O15:AW15)+100,0) -> 146 | H15: =IFERROR(SUM(O15:AW15)/35, "") -> 1.3142857 | I15: =IF(H15>=2.8,"Legendary",IF(H15>=2,"Avenger",IF(H15>=1,"Superhero","Hero"))) -> Superhero | J15: Yes | K15: Yes | L15: No | M15: No | N15: No | O15: 1 | P15: 1 | Q15: 1 | R15: 0 | S15: 2 | T15: 2 | U15: 2 | V15: 2 | W15: 2 | X15: 2 | Y15: 1 | Z15: 1 | AA15: 2 | AB15: 2 | AC15: 1 | AD15: 2 | AE15: 2 | AF15: 1 | AG15: 1 | AH15: 0 | AI15: 1 | AJ15: 1 | AK15: 3 | AL15: 1 | AM15: 3 | AN15: 0 | AO15: 1 | AP15: 0 | AQ15: 2 | AR15: 1 | AS15: 1 | AT15: 1 | AU15: 2 | AV15: 0 | AW15: 1 | AX15: Eric Fleischmann | AY15: Shahid Mahmood | AZ15: Brian Pick, Paul Haig | BA15: James Erskine | BB15: Bob Fizzard | BC15: Jarek Kovak | BD15: 43586 | BE15: =IF(ISBLANK($BD15),"",(TODAY()-$BD15)/30) -> 10.366667 | BF15: 128 | BG15: 146 | BH15: 146 | BI15: =BH15-BG15 -> 0 | BJ15: =(BG15/BF15)-1 -> 0.140625
A16: =ROW()-2 -> 14 | B16: Rangers | C16: IX Workplace Client | D16: SWC/JSCSDK | E16: Argentina | F16: Done | G16: =IF(SUM(O16:AW16)>0,SUM(O16:AW16)+100,0) -> 146 | H16: =IFERROR(SUM(O16:AW16)/35, "") -> 1.3142857 | I16: =IF(H16>=2.8,"Legendary",IF(H16>=2,"Avenger",IF(H16>=1,"Superhero","Hero"))) -> Superhero | J16: No | K16: No | L16: No | M16: No | N16: Yes | O16: 1 | P16: 2 | Q16: 1 | R16: 2 | S16: 3 | T16: 2 | U16: 3 | V16: 3 | W16: 1 | X16: 2 | Y16: 2 | Z16: 1 | AA16: 3 | AB16: 2 | AC16: 2 | AD16: 0 | AE16: 0 | AF16: 0 | AG16: 1 | AH16: 0 | AI16: 0 | AJ16: 1 | AK16: 3 | AL16: 1 | AM16: 2 | AN16: 1 | AO16: 0 | AP16: 0 | AQ16: 1 | AR16: 1 | AS16: 1 | AT16: 2 | AU16: 1 | AV16: 1 | AW16: 0 | AX16: Eric Fleischmann | AY16: Matias Maccaglia | AZ16: Mariano Bonatti | BA16: Mauricio Silclir | BB16: Paul Relf | BC16: Ruby Agarwal | BD16: 43266 | BE16: =IF(ISBLANK($BD16),"",(TODAY()-$BD16)/30) -> 21.033333 | BF16: 139 | BG16: 146 | BH16: 146 | BI16: =BH16-BG16 -> 0
A17: =ROW()-2 -> 15 | B17: GameofScrums | C17: IX-CC | D17: IX Reporting/Analytics | E17: Galway | F17: Done | G17: =IF(SUM(O17:AW17)>0,SUM(O17:AW17)+100,0) -> 145 | H17: =IFERROR(SUM(O17:AW17)/35, "") -> 1.2857143 | I17: =IF(H17>=2.8,"Legendary",IF(H17>=2,"Avenger",IF(H17>=1,"Superhero","Hero"))) -> Superhero | J17: Yes | K17: Yes | L17: No | M17: No | N17: Yes | O17: 2 | P17: 2 | Q17: 1 | R17: 0 | S17: 2 | T17: 2 | U17: 3 | V17: 3 | W17: 1 | X17: 1 | Y17: 1 | Z17: 1 | AA17: 3 | AB17: 3 | AC17: 2 | AD17: 0 | AE17: 1 | AF17: 1 | AG17: 1 | AH17: 1 | AI17: 1 | AJ17: 1 | AK17: 3 | AL17: 3 | AM17: 1 | AN17: 0 | AO17: 0 | AP17: 0 | AQ17: 1 | AR17: 1 | AS17: 0 | AT17: 1 | AU17: 0 | AV17: 2 | AW17: 0 | AX17: Shane Gannon/Sue Keegan | AY17: Trupti Kondavale | AZ17: Chris Dunbar | BA17: Yash Singh | BB17: Wayne Bevan | BC17: Paul D'Arcy | BD17: 43481 | BE17: =IF(ISBLANK($BD17),"",(TODAY()-$BD17)/30) -> 13.866667 | BF17: 159 | BG17: 145 | BH17: 145 | BI17: =BH17-BG17 -> 0
A18: =ROW()-2 -> 16 | B18: Vikings | C18: IX Workplace for Skype for Business | D18: Microsoft Integration | E18: Argentina | F18: Done | G18: =IF(SUM(O18:AW18)>0,SUM(O18:AW18)+100,0) -> 145 | H18: =IFERROR(SUM(O18:AW18)/35, "") -> 1.2857143 | I18: =IF(H18>=2.8,"Legendary",IF(H18>=2,"Avenger",IF(H18>=1,"Superhero","Hero"))) -> Superhero | J18: No | K18: No | L18: No | M18: No | N18: Yes | O18: 1 | P18: 1 | Q18: 2 | R18: 2 | S18: 1 | T18: 1 | U18: 3 | V18: 2 | W18: 2 | X18: 2 | Y18: 3 | Z18: 1 | AA18: 3 | AB18: 3 | AC18: 1 | AD18: 0 | AE18: 0 | AF18: 1 | AG18: 1 | AH18: 0 | AI18: 1 | AJ18: 1 | AK18: 3 | AL18: 2 | AM18: 2 | AN18: 1 | AO18: 0 | AP18: 0 | AQ18: 1 | AR18: 1 | AS18: 0 | AT18: 1 | AU18: 1 | AV18: 0 | AW18: 1 | AX18: Eric Fleischmann | AY18: Diego Cohen | AZ18: Leonardo Marzo | BA18: Gunjan Kak | BB18: Barry O'Connor | BC18: Ruby Agarwal | BD18: 43723 | BE18: =IF(ISBLANK($BD18),"",(TODAY()-$BD18)/30) -> 5.8 | BF18: 135 | BG18: 145 | BH18: 145 | BI18: =BH18-BG18 -> 0
A19: =ROW()-2 -> 17 | B19: ACI | C19: ACI | E19: United States | F19: Done | G19: =IF(SUM(O19:AW19)>0,SUM(O19:AW19)+100,0) -> 144 | H19: =IFERROR(SUM(O19:AW19)/35, "") -> 1.2571429 | I19: =IF(H19>=2.8,"Legendary",IF(H19>=2,"Avenger",IF(H19>=1,"Superhero","Hero"))) -> Superhero | J19: Yes | K19: Partially | L19: No | M19: Yes | N19: Yes | O19: 1 | P19: 1 | Q19: 2 | R19: 1 | S19: 2 | T19: 1 | U19: 2 | V19: 1 | W19: 2 | X19: 1 | Y19: 1 | Z19: 1 | AA19: 2 | AB19: 2 | AC19: 2 | AD19: 1 | AE19: 1 | AF19: 1 | AG19: 1 | AH19: 0 | AI19: 1 | AJ19: 0 | AK19: 3 | AL19: 1 | AM19: 2 | AN19: 1 | AO19: 0 | AP19: 0 | AQ19: 1 | AR19: 2 | AS19: 1 | AT19: 2 | AU19: 2 | AV19: 0 | AW19: 2 | AX19: Eric Fleischmann | AY19: Matthew Peters | AZ19: Michael Salen | BA19: Matthew Peters | BB19: Ernie Wong | BC19: Jeff Hodson | BD19: 43626 | BE19: =IF(ISBLANK($BD19),"",(TODAY()-$BD19)/30) -> 9.0333333 | BF19: 144 | BG19: 144 | BH19: 144 | BI19: =BH19-BG19 -> 0
A20: =ROW()-2 -> 18 | B20: Condor | C20: IX Workplace Client | D20: Equinox Client | E20: Argentina | F20: In Progress | G20: =IF(SUM(O20:AW20)>0,SUM(O20:AW20)+100,0) -> 142 | H20: =IFERROR(SUM(O20:AW20)/35, "") -> 1.2 | I20: =IF(H20>=2.8,"Legendary",IF(H20>=2,"Avenger",IF(H20>=1,"Superhero","Hero"))) -> Superhero | J20: No | K20: No | L20: No | M20: No | N20: No | O20: 1 | P20: 1 | Q20: 1 | R20: 2 | S20: 2 | T20: 2 | U20: 3 | V20: 1 | W20: 2 | X20: 2 | Y20: 1 | Z20: 1 | AA20: 3 | AB20: 2 | AC20: 2 | AD20: 0 | AE20: 0 | AF20: 0 | AG20: 1 | AH20: 0 | AI20: 0 | AJ20: 1 | AK20: 3 | AL20: 1 | AM20: 2 | AN20: 1 | AO20: 0 | AP20: 0 | AQ20: 1 | AR20: 1 | AS20: 1 | AT20: 2 | AU20: 1 | AV20: 1 | AW20: 0 | AX20: Eric Fleischmann | AY20: Luciano Marzo | AZ20: Mariano Zibecchi and Mariano Bonatti | BA20: Mauricio Silclir | BB20: Paul Relf | BC20: Ruby Agarwal | BD20: 43266 | BE20: =IF(ISBLANK($BD20),"",(TODAY()-$BD20)/30) -> 21.033333 | BF20: 139 | BG20: 142 | BH20: 142 | BI20: =BH20-BG20 -> 0
A21: =ROW()-2 -> 19 | B21: Mendieta | C21: IX Workplace Client | D21: CSDK Component & Android client app (all for Vantage) | E21: Argentina | F21: Done | G21: =IF(SUM(O21:AW21)>0,SUM(O21:AW21)+100,0) -> 141 | H21: =IFERROR(SUM(O21:AW21)/35, "") -> 1.1714286 | I21: =IF(H21>=2.8,"Legendary",IF(H21>=2,"Avenger",IF(H21>=1,"Superhero","Hero"))) -> Superhero | J21: No | K21: No | L21: No | M21: No | N21: Yes | O21: 1 | P21: 1 | Q21: 1 | R21: 1 | S21: 2 | T21: 1 | U21: 3 | V21: 3 | W21: 1 | X21: 2 | Y21: 1 | Z21: 1 | AA21: 3 | AB21: 2 | AC21: 2 | AD21: 0 | AE21: 0 | AF21: 0 | AG21: 0 | AH21: 0 | AI21: 1 | AJ21: 1 | AK21: 3 | AL21: 1 | AM21: 3 | AN21: 0 | AO21: 0 | AP21: 0 | AQ21: 1 | AR21: 1 | AS21: 1 | AT21: 2 | AU21: 1 | AV21: 1 | AW21: 0 | AX21: Eric Fleischmann | AY21: Diego Dedacek | AZ21: Mariano Bonatti | BA21: Mauricio Silclir | BB21: Paul Relf | BC21: Ruby Agarwal | BD21: 43266 | BE21: =IF(ISBLANK($BD21),"",(TODAY()-$BD21)/30) -> 21.033333 | BF21: 138 | BG21: 141 | BH21: 141 | BI21: =BH21-BG21 -> 0
A22: =ROW()-2 -> 20 | B22: JaguarScript | C22: IX Workplace Client | D22: JSCSDK | E22: United States | F22: Done | G22: =IF(SUM(O22:AW22)>0,SUM(O22:AW22)+100,0) -> 140 | H22: =IFERROR(SUM(O22:AW22)/35, "") -> 1.1428571 | I22: =IF(H22>=2.8,"Legendary",IF(H22>=2,"Avenger",IF(H22>=1,"Superhero","Hero"))) -> Superhero | J22: No | K22: No | L22: No | M22: No | N22: Yes | O22: 1 | P22: 2 | Q22: 1 | R22: 1 | S22: 3 | T22: 2 | U22: 3 | V22: 0 | W22: 1 | X22: 2 | Y22: 1 | Z22: 1 | AA22: 3 | AB22: 2 | AC22: 2 | AD22: 0 | AE22: 0 | AF22: 0 | AG22: 1 | AH22: 0 | AI22: 0 | AJ22: 1 | AK22: 3 | AL22: 1 | AM22: 2 | AN22: 0 | AO22: 0 | AP22: 0 | AQ22: 1 | AR22: 1 | AS22: 1 | AT22: 2 | AU22: 1 | AV22: 1 | AW22: 0 | AX22: Eric Fleischmann | AY22: Matias Maccaglia | AZ22: Jeff Middleton | BA22: Marc Saunders | BB22: Paul Relf | BC22: Ruby Agarwal | BD22: 43266 | BE22: =IF(ISBLANK($BD22),"",(TODAY()-$BD22)/30) -> 21.033333 | BF22: 139 | BG22: 140 | BH22: 140 | BI22: =BH22-BG22 -> 0
A23: =ROW()-2 -> 21 | B23: POM | C23: POM | E23: India | F23: Done | G23: =IF(SUM(O23:AW23)>0,SUM(O23:AW23)+100,0) -> 139 | H23: =IFERROR(SUM(O23:AW23)/35, "") -> 1.1142857 | I23: =IF(H23>=2.8,"Legendary",IF(H23>=2,"Avenger",IF(H23>=1,"Superhero","Hero"))) -> Superhero | J23: Yes | K23: Yes | L23: No | M23: No | N23: No | O23: 1 | P23: 1 | Q23: 3 | R23: 0 | S23: 2 | T23: 2 | U23: 2 | V23: 3 | W23: 1 | X23: 2 | Y23: 1 | Z23: 1 | AA23: 3 | AB23: 0 | AC23: 1 | AD23: 1 | AE23: 1 | AF23: 1 | AG23: 1 | AH23: 1 | AI23: 1 | AJ23: 1 | AK23: 3 | AL23: 1 | AM23: 1 | AN23: 0 | AO23: 0 | AP23: 0 | AQ23: 1 | AR23: 1 | AS23: 0 | AT23: 1 | AU23: 1 | AV23: 0 | AW23: 0 | AX23: Vijay Bholwani | AY23: Umesh Mahajan | BB23: Michael Gruen | BC23: Sanjog Kotnis | BE23: =IF(ISBLANK($BD23),"",(TODAY()-$BD23)/30) | BF23: 142 | BG23: 139 | BH23: 139 | BI23: =BH23-BG23 -> 0 | BJ23: =(BG23/BF23)-1 -> -0.021126761
A24: =ROW()-2 -> 22 | B24: Sphinx | C24: J SERIES | D24: BLA for RingCentral | E24: Russia | F24: Done | G24: =IF(SUM(O24:AW24)>0,SUM(O24:AW24)+100,0) -> 139 | H24: =IFERROR(SUM(O24:AW24)/35, "") -> 1.1142857 | I24: =IF(H24>=2.8,"Legendary",IF(H24>=2,"Avenger",IF(H24>=1,"Superhero","Hero"))) -> Superhero | J24: No | K24: No | L24: No | M24: No | N24: No | O24: 1 | P24: 1 | Q24: 1 | R24: 0 | S24: 1 | T24: 1 | U24: 2 | V24: 0 | W24: 1 | X24: 2 | Y24: 2 | Z24: 1 | AA24: 2 | AB24: 2 | AC24: 1 | AD24: 2 | AE24: 2 | AF24: 1 | AG24: 1 | AH24: 0 | AI24: 1 | AJ24: 1 | AK24: 3 | AL24: 1 | AM24: 2 | AN24: 0 | AO24: 1 | AP24: 0 | AQ24: 1 | AR24: 1 | AS24: 1 | AT24: 1 | AU24: 1 | AV24: 0 | AW24: 1 | AX24: Eric Fleischmann | AY24: Elena Novikova | AZ24: Cathy Liao, Elena Novikova, Oleg Guschin | BA24: James Erskine | BB24: Bob Fizzard | BC24: Jarek Kovak | BD24: 43586 | BE24: =IF(ISBLANK($BD24),"",(TODAY()-$BD24)/30) -> 10.366667 | BF24: 126 | BG24: 139 | BH24: 139 | BI24: =BH24-BG24 -> 0
A25: =ROW()-2 -> 23 | B25: Hippogriff | C25: J SERIES | D25: BLF, Bluetooth, Audio Codecs | E25: Russia | F25: Done | G25: =IF(SUM(O25:AW25)>0,SUM(O25:AW25)+100,0) -> 138 | H25: =IFERROR(SUM(O25:AW25)/35, "") -> 1.0857143 | I25: =IF(H25>=2.8,"Legendary",IF(H25>=2,"Avenger",IF(H25>=1,"Superhero","Hero"))) -> Superhero | J25: No | K25: No | L25: No | M25: No | N25: No | O25: 1 | P25: 1 | Q25: 1 | R25: 0 | S25: 1 | T25: 1 | U25: 2 | V25: 0 | W25: 1 | X25: 2 | Y25: 1 | Z25: 1 | AA25: 2 | AB25: 2 | AC25: 1 | AD25: 2 | AE25: 2 | AF25: 1 | AG25: 1 | AH25: 0 | AI25: 1 | AJ25: 1 | AK25: 3 | AL25: 1 | AM25: 2 | AN25: 0 | AO25: 1 | AP25: 0 | AQ25: 1 | AR25: 1 | AS25: 1 | AT25: 1 | AU25: 1 | AV25: 0 | AW25: 1 | AX25: Eric Fleischmann | AY25: Anastasiya Loginova | AZ25: Nina Yunusova, Paul Haig, Brian Pick | BA25: James Erskine | BB25: Bob Fizzard | BC25: Jarek Kovak | BD25: 43586 | BE25: =IF(ISBLANK($BD25),"",(TODAY()-$BD25)/30) -> 10.366667 | BF25: 126 | BG25: 138 | BH25: 138 | BI25: =BH25-BG25 -> 0 | BJ25: =(BG25/BF25)-1 -> 0.095238095
A26: =ROW()-2 -> 24 | B26: Assisted Services | C26: IX-CC | D26: Assisted Services | E26: Galway | F26: In Progress | G26: =IF(SUM(O26:AW26)>0,SUM(O26:AW26)+100,0) -> 138 | H26: =IFERROR(SUM(O26:AW26)/35, "") -> 1.0857143 | I26: =IF(H26>=2.8,"Legendary",IF(H26>=2,"Avenger",IF(H26>=1,"Superhero","Hero"))) -> Superhero | J26: Yes | K26: Yes | L26: No | M26: No | N26: Yes | O26: 1 | P26: 2 | Q26: 0 | R26: 0 | S26: 1 | T26: 2 | U26: 2 | V26: 2 | W26: 1 | X26: 1 | Y26: 1 | Z26: 0 | AA26: 2 | AB26: 3 | AC26: 2 | AD26: 0 | AE26: 0 | AF26: 0 | AG26: 0 | AH26: 0 | AI26: 2 | AJ26: 2 | AK26: 3 | AL26: 1 | AM26: 1 | AN26: 0 | AO26: 0 | AP26: 0 | AQ26: 3 | AR26: 2 | AS26: 0 | AT26: 1 | AU26: 1 | AV26: 2 | AW26: 0 | AX26: Shane Gannon/Sue Keegan | AY26: Niall Fallon | AZ26: Paul Kelly | BA26: Paul Kelly & Mike Walsh | BB26: Wayne Bevan | BC26: Paul D'Arcy | BD26: 43523 | BE26: =IF(ISBLANK($BD26),"",(TODAY()-$BD26)/30) -> 12.466667 | BF26: 156 | BG26: 138 | BH26: 138 | BI26: =BH26-BG26 -> 0
A27: =ROW()-2 -> 25 | B27: Analytics 4.0 | C27: Oceana | D27: Analytics 4.0 | E27: Galway | F27: Done | G27: =IF(SUM(O27:AW27)>0,SUM(O27:AW27)+100,0) -> 136 | H27: =IFERROR(SUM(O27:AW27)/35, "") -> 1.0285714 | I27: =IF(H27>=2.8,"Legendary",IF(H27>=2,"Avenger",IF(H27>=1,"Superhero","Hero"))) -> Superhero | J27: Partially | K27: Partially | L27: No | M27: No | N27: Yes | O27: 1 | P27: 3 | Q27: 2 | R27: 1 | S27: 1 | T27: 1 | U27: 2 | V27: 3 | W27: 0 | X27: 1 | Y27: 1 | Z27: 0 | AA27: 2 | AB27: 1 | AC27: 3 | AD27: 0 | AE27: 0 | AF27: 0 | AG27: 1 | AH27: 0 | AI27: 0 | AJ27: 1 | AK27: 3 | AL27: 3 | AM27: 2 | AN27: 1 | AO27: 0 | AP27: 1 | AQ27: 0 | AR27: 1 | AS27: 0 | AT27: 1 | AU27: 0 | AV27: 0 | AW27: 0 | AX27: Dejan Savic | AY27: Dejan Savic | BB27: David Mulry | BC27: Eugene Garvin | BD27: 43691 | BE27: =IF(ISBLANK($BD27),"",(TODAY()-$BD27)/30) -> 6.8666667 | BF27: 159 | BG27: 136 | BH27: 136 | BI27: =BH27-BG27 -> 0 | BJ27: =(BG27/BF27)-1 -> -0.14465409
A28: =ROW()-2 -> 26 | B28: Analytics 3.x | C28: Oceana | D28: Analytics 3.x | E28: Galway | F28: Done | G28: =IF(SUM(O28:AW28)>0,SUM(O28:AW28)+100,0) -> 136 | H28: =IFERROR(SUM(O28:AW28)/35, "") -> 1.0285714 | I28: =IF(H28>=2.8,"Legendary",IF(H28>=2,"Avenger",IF(H28>=1,"Superhero","Hero"))) -> Superhero | J28: Partially | K28: Yes | L28: No | M28: No | N28: Yes | O28: 1 | P28: 3 | Q28: 1 | R28: 3 | S28: 1 | T28: 1 | U28: 2 | V28: 3 | W28: 0 | X28: 1 | Y28: 1 | Z28: 0 | AA28: 2 | AB28: 1 | AC28: 3 | AD28: 0 | AE28: 0 | AF28: 0 | AG28: 1 | AH28: 0 | AI28: 0 | AJ28: 1 | AK28: 3 | AL28: 3 | AM28: 2 | AN28: 1 | AO28: 0 | AP28: 1 | AQ28: 0 | AR28: 0 | AS28: 0 | AT28: 1 | AU28: 0 | AV28: 0 | AW28: 0 | AX28: Dejan Savic | AY28: Dejan Savic | AZ28: Dejan Savic | BB28: David Mulry | BC28: Eugene Garvin | BD28: 43621 | BE28: =IF(ISBLANK($BD28),"",(TODAY()-$BD28)/30) -> 9.2 | BF28: 156 | BG28: 136 | BH28: 136 | BI28: =BH28-BG28 -> 0
A29: =ROW()-2 -> 27 | B29: Dragon | C29: J SERIES | D29: Avaya Cloud Offer (4.0.5.0) | E29: Russia | F29: Done | G29: =IF(SUM(O29:AW29)>0,SUM(O29:AW29)+100,0) -> 136 | H29: =IFERROR(SUM(O29:AW29)/35, "") -> 1.0285714 | I29: =IF(H29>=2.8,"Legendary",IF(H29>=2,"Avenger",IF(H29>=1,"Superhero","Hero"))) -> Superhero | J29: No | K29: No | L29: No | M29: No | N29: No | O29: 1 | P29: 1 | Q29: 1 | R29: 0 | S29: 1 | T29: 1 | U29: 2 | V29: 0 | W29: 1 | X29: 2 | Y29: 1 | Z29: 1 | AA29: 2 | AB29: 2 | AC29: 1 | AD29: 1 | AE29: 1 | AF29: 1 | AG29: 1 | AH29: 0 | AI29: 1 | AJ29: 1 | AK29: 3 | AL29: 1 | AM29: 2 | AN29: 0 | AO29: 1 | AP29: 0 | AQ29: 1 | AR29: 1 | AS29: 1 | AT29: 1 | AU29: 1 | AV29: 0 | AW29: 1 | AX29: Eric Fleischmann | AY29: Mikhail Tagirov | AZ29: Nina Yunusova, Paul Haig, Brian Pick | BA29: James Erskine | BB29: Bob Fizzard | BC29: Jarek Kovak | BD29: 43586 | BE29: =IF(ISBLANK($BD29),"",(TODAY()-$BD29)/30) -> 10.366667 | BF29: 126 | BG29: 136 | BH29: 136 | BI29: =BH29-BG29 -> 0
A30: =ROW()-2 -> 28 | B30: Phoenix | C30: J SERIES | D30: Mercury phones | E30: Russia | F30: Done | G30: =IF(SUM(O30:AW30)>0,SUM(O30:AW30)+100,0) -> 136 | H30: =IFERROR(SUM(O30:AW30)/35, "") -> 1.0285714 | I30: =IF(H30>=2.8,"Legendary",IF(H30>=2,"Avenger",IF(H30>=1,"Superhero","Hero"))) -> Superhero | J30: No | K30: No | L30: No | M30: No | N30: No | O30: 1 | P30: 1 | Q30: 1 | R30: 0 | S30: 1 | T30: 1 | U30: 2 | V30: 0 | W30: 1 | X30: 2 | Y30: 1 | Z30: 1 | AA30: 3 | AB30: 2 | AC30: 1 | AD30: 2 | AE30: 1 | AF30: 0 | AG30: 1 | AH30: 0 | AI30: 1 | AJ30: 1 | AK30: 3 | AL30: 1 | AM30: 1 | AN30: 1 | AO30: 0 | AP30: 0 | AQ30: 1 | AR30: 1 | AS30: 1 | AT30: 1 | AU30: 1 | AV30: 0 | AW30: 1 | AX30: Eric Fleischmann | AY30: Andrey Khudenkikh | AZ30: Andrey Khudenkikh | BA30: James Erskine | BB30: Bob Fizzard | BC30: Jarek Kovak | BD30: 43586 | BE30: =IF(ISBLANK($BD30),"",(TODAY()-$BD30)/30) -> 10.366667 | BF30: 126 | BG30: 136 | BH30: 136 | BI30: =BH30-BG30 -> 0 | BJ30: =(BG30/BF30)-1 -> 0.079365079
A31: =ROW()-2 -> 29 | B31: Usage Metering | C31: Usage Metering | D31: - | E31: Israel | F31: Done | G31: =IF(SUM(O31:AW31)>0,SUM(O31:AW31)+100,0) -> 134 | H31: =IFERROR(SUM(O31:AW31)/35, "") -> 0.97142857 | I31: =IF(H31>=2.8,"Legendary",IF(H31>=2,"Avenger",IF(H31>=1,"Superhero","Hero"))) -> Hero | J31: Partially | K31: Yes | L31: No | M31: No | N31: No | O31: 1 | P31: 1 | Q31: 2 | R31: 1 | S31: 1 | T31: 1 | U31: 1 | V31: 1 | W31: 1 | X31: 2 | Y31: 0 | Z31: 0 | AA31: 2 | AB31: 2 | AC31: 2 | AD31: 0 | AE31: 1 | AF31: 1 | AG31: 1 | AH31: 0 | AI31: 0 | AJ31: 0 | AK31: 3 | AL31: 3 | AM31: 1 | AN31: 2 | AO31: 0 | AP31: 0 | AQ31: 0 | AR31: 1 | AS31: 0 | AT31: 2 | AU31: 1 | AV31: 0 | AW31: 0 | AX31: Erez Morabia | AY31: Zvika Oskar | AZ31: Eyal Serero (P) | BA31: Eyal Serero | BB31: Orly Shechtman | BC31: Becky Richardson | BD31: 43586 | BE31: =IF(ISBLANK($BD31),"",(TODAY()-$BD31)/30) -> 10.366667 | BF31: 136 | BG31: 134 | BH31: 134 | BI31: =BH31-BG31 -> 0
A32: =ROW()-2 -> 30 | B32: Unicorn | C32: J SERIES | D32: J189 / J189 UI components | E32: Russia | F32: Done | G32: =IF(SUM(O32:AW32)>0,SUM(O32:AW32)+100,0) -> 134 | H32: =IFERROR(SUM(O32:AW32)/35, "") -> 0.97142857 | I32: =IF(H32>=2.8,"Legendary",IF(H32>=2,"Avenger",IF(H32>=1,"Superhero","Hero"))) -> Hero | J32: No | K32: No | L32: No | M32: No | N32: No | O32: 1 | P32: 1 | Q32: 1 | R32: 0 | S32: 1 | T32: 1 | U32: 2 | V32: 0 | W32: 1 | X32: 1 | Y32: 1 | Z32: 1 | AA32: 2 | AB32: 2 | AC32: 1 | AD32: 2 | AE32: 2 | AF32: 1 | AG32: 1 | AH32: 0 | AI32: 1 | AJ32: 1 | AK32: 3 | AL32: 1 | AM32: 1 | AN32: 0 | AO32: 0 | AP32: 0 | AQ32: 1 | AR32: 1 | AS32: 1 | AT32: 0 | AU32: 1 | AV32: 0 | AW32: 1 | AX32: Eric Fleischmann | AY32: Svetlana Podogova | AZ32: Stephane Lefebvre | BA32: James Erskine | BB32: Bob Fizzard | BC32: Jarek Kovak | BD32: 43586 | BE32: =IF(ISBLANK($BD32),"",(TODAY()-$BD32)/30) -> 10.366667 | BF32: 126 | BG32: 134 | BH32: 134 | BI32: =BH32-BG32 -> 0 | BJ32: =(BG32/BF32)-1 -> 0.063492063
A33: =ROW()-2 -> 31 | B33: Wyvern | C33: J SERIES | D33: LDAP, IPv6 | E33: Russia | F33: Done | G33: =IF(SUM(O33:AW33)>0,SUM(O33:AW33)+100,0) -> 134 | H33: =IFERROR(SUM(O33:AW33)/35, "") -> 0.97142857 | I33: =IF(H33>=2.8,"Legendary",IF(H33>=2,"Avenger",IF(H33>=1,"Superhero","Hero"))) -> Hero | J33: No | K33: No | L33: No | M33: No | N33: No | O33: 1 | P33: 1 | Q33: 1 | R33: 0 | S33: 1 | T33: 1 | U33: 2 | V33: 0 | W33: 1 | X33: 2 | Y33: 1 | Z33: 1 | AA33: 2 | AB33: 2 | AC33: 1 | AD33: 1 | AE33: 1 | AF33: 1 | AG33: 1 | AH33: 0 | AI33: 1 | AJ33: 1 | AK33: 3 | AL33: 1 | AM33: 1 | AN33: 0 | AO33: 1 | AP33: 0 | AQ33: 1 | AR33: 1 | AS33: 0 | AT33: 1 | AU33: 1 | AV33: 0 | AW33: 1 | AX33: Eric Fleischmann | AY33: Alex Lyubimov | AZ33: Nina Yunusova, Paul Haig, Brian Pick | BA33: James Erskine | BB33: Bob Fizzard | BC33: Jarek Kovak | BD33: 43586 | BE33: =IF(ISBLANK($BD33),"",(TODAY()-$BD33)/30) -> 10.366667 | BF33: 126 | BG33: 134 | BH33: 134 | BI33: =BH33-BG33 -> 0
A34: =ROW()-2 -> 32 | B34: Ahaṁ Brahmāsmi | C34: IX-CC | D34: Flex/CSP Pune | E34: India | F34: Done | G34: =IF(SUM(O34:AW34)>0,SUM(O34:AW34)+100,0) -> 134 | H34: =IFERROR(SUM(O34:AW34)/35, "") -> 0.97142857 | I34: =IF(H34>=2.8,"Legendary",IF(H34>=2,"Avenger",IF(H34>=1,"Superhero","Hero"))) -> Hero | J34: No | K34: No | L34: No | M34: No | N34: Yes | O34: 1 | P34: 2 | Q34: 1 | R34: 0 | S34: 1 | T34: 2 | U34: 3 | V34: 2 | W34: 1 | X34: 2 | Y34: 1 | Z34: 1 | AA34: 1 | AB34: 2 | AC34: 1 | AD34: 0 | AE34: 0 | AF34: 1 | AG34: 1 | AH34: 1 | AI34: 1 | AJ34: 1 | AK34: 3 | AL34: 3 | AM34: 1 | AN34: 0 | AO34: 0 | AP34: 0 | AQ34: 0 | AR34: 1 | AS34: 0 | AT34: 0 | AU34: 0 | AV34: 0 | AW34: 0 | AX34: Vijay Bholwani | AY34: Barkha Shukla | AZ34: Shankar Makjija | BA34: Birendra Sinha & Anjali Doiphode | BB34: Mike Killeen | BC34: Paul D'Arcy | BD34: 43481 | BE34: =IF(ISBLANK($BD34),"",(TODAY()-$BD34)/30) -> 13.866667 | BF34: 129 | BG34: 134 | BH34: 134 | BI34: =BH34-BG34 -> 0 | BJ34: =(BG34/BF34)-1 -> 0.03875969
A35: =ROW()-2 -> 33 | B35: Conf EPs Sweden | C35: Conf EPs | D35: - | E35: Sweden | F35: Done | G35: =IF(SUM(O35:AW35)>0,SUM(O35:AW35)+100,0) -> 133 | H35: =IFERROR(SUM(O35:AW35)/35, "") -> 0.94285714 | I35: =IF(H35>=2.8,"Legendary",IF(H35>=2,"Avenger",IF(H35>=1,"Superhero","Hero"))) -> Hero | J35: Yes | K35: Yes | L35: No | M35: No | N35: No | O35: 1 | P35: 2 | Q35: 2 | R35: 3 | S35: 1 | T35: 2 | U35: 2 | V35: 2 | W35: 1 | X35: 3 | Y35: 0 | Z35: 0 | AA35: 0 | AB35: 0 | AC35: 3 | AD35: 1 | AE35: 1 | AF35: 1 | AG35: 1 | AH35: 0 | AI35: 0 | AJ35: 1 | AK35: 0 | AL35: 1 | AM35: 0 | AN35: 0 | AO35: 0 | AP35: 0 | AQ35: 0 | AR35: 1 | AS35: 1 | AT35: 2 | AU35: 1 | AV35: 0 | AW35: 0 | AX35: Shane Gannon/Erez Morabia | AY35: Magnus Häggström | AZ35: Jonas Aronsson | BA35: Peter Fredriksson | BB35: Torbjörn Karlsson | BC35: Peter Fredriksson | BD35: 43801 | BE35: =IF(ISBLANK($BD35),"",(TODAY()-$BD35)/30) -> 3.2 | BF35: 128 | BG35: 129 | BH35: 133 | BI35: =BH35-BG35 -> 4
A36: =ROW()-2 -> 34 | B36: Bahubali | C36: AWFOS | E36: India | F36: Done | G36: =IF(SUM(O36:AW36)>0,SUM(O36:AW36)+100,0) -> 133 | H36: =IFERROR(SUM(O36:AW36)/35, "") -> 0.94285714 | I36: =IF(H36>=2.8,"Legendary",IF(H36>=2,"Avenger",IF(H36>=1,"Superhero","Hero"))) -> Hero | J36: No | K36: Yes | L36: No | M36: No | N36: Yes | O36: 1 | P36: 1 | Q36: 2 | R36: 0 | S36: 2 | T36: 2 | U36: 2 | V36: 1 | W36: 1 | X36: 2 | Y36: 1 | Z36: 1 | AA36: 1 | AB36: 1 | AC36: 1 | AD36: 1 | AE36: 1 | AF36: 1 | AG36: 1 | AH36: 1 | AI36: 1 | AJ36: 1 | AK36: 3 | AL36: 1 | AM36: 1 | AN36: 0 | AO36: 0 | AP36: 0 | AQ36: 1 | AR36: 1 | AS36: 0 | AT36: 0 | AU36: 0 | AV36: 0 | AW36: 0 | AX36: Vijay Bholwani | AY36: Guru Ayondhyanath | BB36: William Jolicoeur | BC36: Pat Lawless | BD36: 43466 | BE36: =IF(ISBLANK($BD36),"",(TODAY()-$BD36)/30) -> 14.366667 | BF36: 138 | BG36: 133 | BH36: 133 | BI36: =BH36-BG36 -> 0
A37: =ROW()-2 -> 35 | B37: Assisted 3.x | C37: Oceana | D37: Assisted 3.x | E37: Galway | F37: Done | G37: =IF(SUM(O37:AW37)>0,SUM(O37:AW37)+100,0) -> 131 | H37: =IFERROR(SUM(O37:AW37)/35, "") -> 0.88571429 | I37: =IF(H37>=2.8,"Legendary",IF(H37>=2,"Avenger",IF(H37>=1,"Superhero","Hero"))) -> Hero | J37: Partially | K37: Partially | L37: No | M37: No | N37: Yes | O37: 0 | P37: 2 | Q37: 0 | R37: 1 | S37: 1 | T37: 1 | U37: 2 | V37: 3 | W37: 0 | X37: 1 | Y37: 1 | Z37: 0 | AA37: 2 | AB37: 1 | AC37: 3 | AD37: 0 | AE37: 0 | AF37: 0 | AG37: 1 | AH37: 0 | AI37: 0 | AJ37: 1 | AK37: 3 | AL37: 3 | AM37: 2 | AN37: 1 | AO37: 0 | AP37: 1 | AQ37: 0 | AR37: 0 | AS37: 0 | AT37: 1 | AU37: 0 | AV37: 0 | AW37: 0 | AX37: Dejan Savic | AY37: Dejan Savic | BA37: Paul Kelly | BB37: Shane O'Neil | BC37: Eugene Garvin | BD37: 43691 | BE37: =IF(ISBLANK($BD37),"",(TODAY()-$BD37)/30) -> 6.8666667 | BF37: 150 | BG37: 131 | BH37: 131 | BI37: =BH37-BG37 -> 0
A38: =ROW()-2 -> 36 | B38: Black Pearl | C38: J SERIES | D38: RTCP XR for Ring Central, Web UI | E38: India | F38: Done | G38: =IF(SUM(O38:AW38)>0,SUM(O38:AW38)+100,0) -> 131 | H38: =IFERROR(SUM(O38:AW38)/35, "") -> 0.88571429 | I38: =IF(H38>=2.8,"Legendary",IF(H38>=2,"Avenger",IF(H38>=1,"Superhero","Hero"))) -> Hero | J38: Partially | K38: Yes | L38: No | M38: No | N38: Yes | O38: 1 | P38: 1 | Q38: 1 | R38: 0 | S38: 1 | T38: 2 | U38: 2 | V38: 1 | W38: 0 | X38: 1 | Y38: 0 | Z38: 1 | AA38: 3 | AB38: 1 | AC38: 1 | AD38: 1 | AE38: 1 | AF38: 1 | AG38: 1 | AH38: 0 | AI38: 1 | AJ38: 1 | AK38: 3 | AL38: 1 | AM38: 1 | AN38: 0 | AO38: 0 | AP38: 0 | AQ38: 0 | AR38: 1 | AS38: 1 | AT38: 1 | AU38: 0 | AV38: 0 | AW38: 1 | AX38: Vijay Bholwani | AY38: Gyanesh Soni | AZ38: Debakanta Jena | BA38: Anand Padhye | BB38: Bob Fizzard | BC38: Jarek Kovak | BD38: 43586 | BE38: =IF(ISBLANK($BD38),"",(TODAY()-$BD38)/30) -> 10.366667 | BF38: 120 | BG38: 129 | BH38: 129 | BI38: =BH38-BG38 -> 0 | BJ38: =(BG38/BF38)-1 -> 0.075
A39: =ROW()-2 -> 37 | B39: Comrades | C39: Conf EPs | D39: - | E39: Russia | F39: Done | G39: =IF(SUM(O39:AW39)>0,SUM(O39:AW39)+100,0) -> 131 | H39: =IFERROR(SUM(O39:AW39)/35, "") -> 0.88571429 | I39: =IF(H39>=2.8,"Legendary",IF(H39>=2,"Avenger",IF(H39>=1,"Superhero","Hero"))) -> Hero | J39: Yes | K39: Yes | L39: No | M39: No | N39: No | O39: 1 | P39: 1 | Q39: 2 | R39: 2 | S39: 1 | T39: 2 | U39: 2 | V39: 0 | W39: 1 | X39: 3 | Y39: 0 | Z39: 0 | AA39: 0 | AB39: 2 | AC39: 3 | AD39: 1 | AE39: 1 | AF39: 1 | AG39: 1 | AH39: 0 | AI39: 0 | AJ39: 1 | AK39: 0 | AL39: 1 | AM39: 0 | AN39: 0 | AO39: 0 | AP39: 0 | AQ39: 0 | AR39: 1 | AS39: 1 | AT39: 2 | AU39: 1 | AV39: 0 | AW39: 0 | AX39: Shane Gannon/Erez Morabia | AY39: Dmitry Noskov | AZ39: Jonas Aronsson | BA39: Peter Fredriksson | BB39: Torbjörn Karlsson | BC39: Peter Fredriksson | BD39: 43801 | BE39: =IF(ISBLANK($BD39),"",(TODAY()-$BD39)/30) -> 3.2 | BF39: 128 | BG39: 129 | BH39: 131 | BI39: =BH39-BG39 -> 2
A40: =ROW()-2 -> 38 | B40: PLATFORMS | C40: PLATFORMS | E40: India | F40: Done | G40: =IF(SUM(O40:AW40)>0,SUM(O40:AW40)+100,0) -> 130 | H40: =IFERROR(SUM(O40:AW40)/35, "") -> 0.85714286 | I40: =IF(H40>=2.8,"Legendary",IF(H40>=2,"Avenger",IF(H40>=1,"Superhero","Hero"))) -> Hero | J40: Yes | K40: Yes | L40: No | M40: No | N40: No | O40: 1 | P40: 0 | Q40: 1 | R40: 0 | S40: 1 | T40: 2 | U40: 2 | V40: 1 | W40: 2 | X40: 0 | Y40: 1 | Z40: 1 | AA40: 0 | AB40: 2 | AC40: 3 | AD40: 0 | AE40: 1 | AF40: 1 | AG40: 1 | AH40: 1 | AI40: 1 | AJ40: 1 | AK40: 3 | AL40: 1 | AM40: 1 | AN40: 0 | AO40: 0 | AP40: 0 | AQ40: 0 | AR40: 1 | AS40: 0 | AT40: 1 | AU40: 0 | AV40: 0 | AW40: 0 | AX40: Vijay Bholwani | AY40: - | BB40: Jeff R | BC40: Richard W | BD40: 43678 | BE40: =IF(ISBLANK($BD40),"",(TODAY()-$BD40)/30) -> 7.3 | BF40: 125 | BG40: 130 | BH40: 130 | BI40: =BH40-BG40 -> 0
...

Sheet Eric
A4: Rank | B4: Team Name | C4: Product | D4: Component | E4: Location | F4: Reviewed by ACT | G4: Current Score | H4: Average Score | I4: Badge | J4: Product Owner | K4: Scrum Master | L4: Multi function team | M4: DoD | N4: DoR | O4: AIM ceremonies | P4: Scrum area | Q4: Story Points | R4: Tasking | S4: Backlog grooming (sprint) | T4: Backlog grooming (release) | U4: Demo | V4: Retro | W4: Unified backlog | X4: Personas | Y4: Story mapping | Z4: Tech debt strategy | AA4: Defect management strategy | AB4: AIM JIRA structure | AC4: Release tracker | AD4: Sprint burndown | AE4: BDD | AF4: Test automation | AG4: CI/CD | AH4: Shift-left adoption | AI4: Single branch strategy | AJ4: Reducing WIP | AK4: Engineering 360 | AL4: Customer engagement
A5: 13 | B5: Kraken | C5: J SERIES | D5: RingCentral ACO/RCO features | E5: Canada | F5: Done | G5: 146 | H5: 1.3142857 | I5: Superhero | J5: 1 | K5: 1 | L5: 1 | M5: 2 | N5: 2 | O5: 2 | P5: 2 | Q5: 2 | R5: 2 | S5: 1 | T5: 1 | U5: 2 | V5: 2 | W5: 1 | X5: 2 | Y5: 2 | Z5: 1 | AA5: 1 | AB5: 3 | AC5: 1 | AD5: 3 | AE5: 1 | AF5: 2 | AG5: 1 | AH5: 1 | AI5: 1 | AJ5: 2 | AK5: 0 | AL5: 1
A6: 21 | B6: Sphinx | C6: J SERIES | D6: BLA for RingCentral | E6: Russia | F6: Done | G6: 139 | H6: 1.1142857 | I6: Superhero | J6: 1 | K6: 1 | L6: 1 | M6: 1 | N6: 1 | O6: 2 | P6: 0 | Q6: 1 | R6: 2 | S6: 2 | T6: 1 | U6: 2 | V6: 2 | W6: 1 | X6: 2 | Y6: 2 | Z6: 1 | AA6: 1 | AB6: 3 | AC6: 1 | AD6: 2 | AE6: 1 | AF6: 1 | AG6: 1 | AH6: 1 | AI6: 1 | AJ6: 1 | AK6: 0 | AL6: 1
A7: 23 | B7: Hippogriff | C7: J SERIES | D7: BLF, Bluetooth, Audio Codecs | E7: Russia | F7: Done | G7: 138 | H7: 1.0857143 | I7: Superhero | J7: 1 | K7: 1 | L7: 1 | M7: 1 | N7: 1 | O7: 2 | P7: 0 | Q7: 1 | R7: 2 | S7: 1 | T7: 1 | U7: 2 | V7: 2 | W7: 1 | X7: 2 | Y7: 2 | Z7: 1 | AA7: 1 | AB7: 3 | AC7: 1 | AD7: 2 | AE7: 1 | AF7: 1 | AG7: 1 | AH7: 1 | AI7: 1 | AJ7: 1 | AK7: 0 | AL7: 1
A8: 25 | B8: Dragon | C8: J SERIES | D8: Avaya Cloud Offer (4.0.5.0) | E8: Russia | F8: Done | G8: 136 | H8: 1.0285714 | I8: Superhero | J8: 1 | K8: 1 | L8: 1 | M8: 1 | N8: 1 | O8: 2 | P8: 0 | Q8: 1 | R8: 2 | S8: 1 | T8: 1 | U8: 2 | V8: 2 | W8: 1 | X8: 1 | Y8: 1 | Z8: 1 | AA8: 1 | AB8: 3 | AC8: 1 | AD8: 2 | AE8: 1 | AF8: 1 | AG8: 1 | AH8: 1 | AI8: 1 | AJ8: 1 | AK8: 0 | AL8: 1
A9: 28 | B9: Phoenix | C9: J SERIES | D9: Mercury phones | E9: Russia | F9: Done | G9: 136 | H9: 1.0285714 | I9: Superhero | J9: 1 | K9: 1 | L9: 1 | M9: 1 | N9: 1 | O9: 2 | P9: 0 | Q9: 1 | R9: 2 | S9: 1 | T9: 1 | U9: 3 | V9: 2 | W9: 1 | X9: 2 | Y9: 1 | Z9: 1 | AA9: 1 | AB9: 3 | AC9: 1 | AD9: 1 | AE9: 0 | AF9: 1 | AG9: 1 | AH9: 1 | AI9: 1 | AJ9: 1 | AK9: 0 | AL9: 1
A10: 30 | B10: Unicorn | C10: J SERIES | D10: J189 / J189 UI components | E10: Russia | F10: Done | G10: 134 | H10: 0.97142857 | I10: Hero | J10: 1 | K10: 1 | L10: 1 | M10: 1 | N10: 1 | O10: 2 | P10: 0 | Q10: 1 | R10: 1 | S10: 1 | T10: 1 | U10: 2 | V10: 2 | W10: 1 | X10: 2 | Y10: 2 | Z10: 1 | AA10: 1 | AB10: 3 | AC10: 1 | AD10: 1 | AE10: 0 | AF10: 1 | AG10: 1 | AH10: 1 | AI10: 0 | AJ10: 1 | AK10: 0 | AL10: 1
A11: 32 | B11: Wyvern | C11: J SERIES | D11: LDAP, IPv6 | E11: Russia | F11: Done | G11: 134 | H11: 0.97142857 | I11: Hero | J11: 1 | K11: 1 | L11: 1 | M11: 1 | N11: 1 | O11: 2 | P11: 0 | Q11: 1 | R11: 2 | S11: 1 | T11: 1 | U11: 2 | V11: 2 | W11: 1 | X11: 1 | Y11: 1 | Z11: 1 | AA11: 1 | AB11: 3 | AC11: 1 | AD11: 1 | AE11: 1 | AF11: 1 | AG11: 1 | AH11: 0 | AI11: 1 | AJ11: 1 | AK11: 0 | AL11: 1
A12: 36 | B12: Black Pearl | C12: J SERIES | E12: India | F12: Done | G12: 129 | H12: 0.82857143 | I12: Hero | J12: 1 | K12: 1 | L12: 1 | M12: 1 | N12: 2 | O12: 1 | P12: 1 | Q12: 0 | R12: 0 | S12: 0 | T12: 1 | U12: 3 | V12: 1 | W12: 1 | X12: 1 | Y12: 1 | Z12: 1 | AA12: 1 | AB12: 3 | AC12: 1 | AD12: 1 | AE12: 0 | AF12: 0 | AG12: 1 | AH12: 1 | AI12: 1 | AJ12: 0 | AK12: 0 | AL12: 1
J14: Product Owner | K14: Scrum Master | L14: Multi function team | M14: DoD | N14: DoR | O14: AIM ceremonies | P14: Scrum area | Q14: Story Points | R14: Tasking | S14: Backlog grooming (sprint) | T14: Backlog grooming (release) | U14: Demo | V14: Retro | W14: Unified backlog | X14: Personas | Y14: Story mapping | Z14: Tech debt strategy | AA14: Defect management strategy | AB14: AIM JIRA structure | AC14: Release tracker | AD14: Sprint burndown | AE14: BDD | AF14: Test automation | AG14: CI/CD | AH14: Shift-left adoption | AI14: Single branch strategy | AJ14: Reducing WIP | AK14: Engineering 360 | AL14: Customer engagement
J15: =SUM(J5:J12)/COUNT(J5:J12) -> 1 | K15: =SUM(K5:K12)/COUNT(K5:K12) -> 1 | L15: =SUM(L5:L12)/COUNT(L5:L12) -> 1 | M15: =SUM(M5:M12)/COUNT(M5:M12) -> 1.125 | N15: =SUM(N5:N12)/COUNT(N5:N12) -> 1.25 | O15: =SUM(O5:O12)/COUNT(O5:O12) -> 1.875 | P15: =SUM(P5:P12)/COUNT(P5:P12) -> 0.375 | Q15: =SUM(Q5:Q12)/COUNT(Q5:Q12) -> 1 | ... AL15: =SUM(AL5:AL12)/COUNT(AL5:AL12) -> 1
A43: Rank | B43: Team Name | C43: Product | D43: Component | E43: Location | F43: Reviewed by ACT | G43: Current Score | H43: Average Score | I43: Badge | J43: Product Owner | K43: Scrum Master | L43: Multi function team | M43: Multi component team | N43: DoD | O43: DoR | P43: AIM ceremonies | Q43: Scrum area | R43: Story Points | S43: Tasking | T43: Backlog grooming (sprint) | U43: Backlog grooming (release) | V43: Demo | W43: Retro | X43: Unified backlog | Y43: Personas | Z43: Story mapping | AA43: User story template | AB43: Tech story template | AC43: Spikes template | AD43: Tech debt strategy | AE43: Defect management strategy | AF43: AIM JIRA structure | AG43: Release tracker | AH43: Sprint burndown | AI43: Time to Value Delivery | AJ43: BDD | AK43: TDD | AL43: Test automation | AM43: CI/CD | AN43: Shift-left adoption | AO43: Single branch strategy | AP43: Reducing WIP | AQ43: Engineering 360 | AR43: Customer engagement | AS43: AIM Coach | AT43: SM | AU43: PO | AV43: Eng Manager | AW43: PLM | AX43: Eng Sponsor (Director) | AY43: Start Date | AZ43: AIM Age (month) | BA43: 2019 Nov | BB43: 2019 Dec | BC43: 2020 Jan | BD43: Progress
A44: 13 | B44: Kraken | C44: J SERIES | D44: RingCentral ACO/RCO features | E44: Canada | F44: Done | G44: 146 | H44: 1.3142857 | I44: Superhero | J44: 1 | K44: 1 | L44: 1 | M44: 0 | N44: 2 | O44: 2 | P44: 2 | Q44: 2 | R44: 2 | S44: 2 | T44: 1 | U44: 1 | V44: 2 | W44: 2 | X44: 1 | Y44: 2 | Z44: 2 | AA44: 1 | AB44: 1 | AC44: 0 | AD44: 1 | AE44: 1 | AF44: 3 | AG44: 1 | AH44: 3 | AI44: 0 | AJ44: 1 | AK44: 0 | AL44: 2 | AM44: 1 | AN44: 1 | AO44: 1 | AP44: 2 | AQ44: 0 | AR44: 1 | AS44: Eric Fleischmann | AT44: Shahid Mahmood | AU44: Brian Pick, Paul Haig | AV44: James Erskine | AW44: Bob Fizzard | AX44: Jarek Kovak | AY44: 43586 | AZ44: 8.3 | BA44: 128 | BB44: 146 | BC44: 146 | BD44: 0
A45: 21 | B45: Sphinx | C45: J SERIES | D45: BLA for RingCentral | E45: Russia | F45: Done | G45: 139 | H45: 1.1142857 | I45: Superhero | J45: 1 | K45: 1 | L45: 1 | M45: 0 | N45: 1 | O45: 1 | P45: 2 | Q45: 0 | R45: 1 | S45: 2 | T45: 2 | U45: 1 | V45: 2 | W45: 2 | X45: 1 | Y45: 2 | Z45: 2 | AA45: 1 | AB45: 1 | AC45: 0 | AD45: 1 | AE45: 1 | AF45: 3 | AG45: 1 | AH45: 2 | AI45: 0 | AJ45: 1 | AK45: 0 | AL45: 1 | AM45: 1 | AN45: 1 | AO45: 1 | AP45: 1 | AQ45: 0 | AR45: 1 | AS45: Eric Fleischmann | AT45: Elena Novikova | AU45: Cathy Liao, Elena Novikova, Oleg Guschin | AV45: James Erskine | AW45: Bob Fizzard | AX45: Jarek Kovak | AY45: 43586 | AZ45: 8.3 | BA45: 126 | BB45: 139 | BC45: 139 | BD45: 0
A46: 23 | B46: Hippogriff | C46: J SERIES | D46: BLF, Bluetooth, Audio Codecs | E46: Russia | F46: Done | G46: 138 | H46: 1.0857143 | I46: Superhero | J46: 1 | K46: 1 | L46: 1 | M46: 0 | N46: 1 | O46: 1 | P46: 2 | Q46: 0 | R46: 1 | S46: 2 | T46: 1 | U46: 1 | V46: 2 | W46: 2 | X46: 1 | Y46: 2 | Z46: 2 | AA46: 1 | AB46: 1 | AC46: 0 | AD46: 1 | AE46: 1 | AF46: 3 | AG46: 1 | AH46: 2 | AI46: 0 | AJ46: 1 | AK46: 0 | AL46: 1 | AM46: 1 | AN46: 1 | AO46: 1 | AP46: 1 | AQ46: 0 | AR46: 1 | AS46: Eric Fleischmann | AT46: Anastasiya Loginova | AU46: Nina Yunusova, Paul Haig, Brian Pick | AV46: James Erskine | AW46: Bob Fizzard | AX46: Jarek Kovak | AY46: 43586 | AZ46: 8.3 | BA46: 126 | BB46: 138 | BC46: 138 | BD46: 0
A47: 25 | B47: Dragon | C47: J SERIES | D47: Avaya Cloud Offer (4.0.5.0) | E47: Russia | F47: Done | G47: 136 | H47: 1.0285714 | I47: Superhero | J47: 1 | K47: 1 | L47: 1 | M47: 0 | N47: 1 | O47: 1 | P47: 2 | Q47: 0 | R47: 1 | S47: 2 | T47: 1 | U47: 1 | V47: 2 | W47: 2 | X47: 1 | Y47: 1 | Z47: 1 | AA47: 1 | AB47: 1 | AC47: 0 | AD47: 1 | AE47: 1 | AF47: 3 | AG47: 1 | AH47: 2 | AI47: 0 | AJ47: 1 | AK47: 0 | AL47: 1 | AM47: 1 | AN47: 1 | AO47: 1 | AP47: 1 | AQ47: 0 | AR47: 1 | AS47: Eric Fleischmann | AT47: Mikhail Tagirov | AU47: Nina Yunusova, Paul Haig, Brian Pick | AV47: James Erskine | AW47: Bob Fizzard | AX47: Jarek Kovak | AY47: 43586 | AZ47: 8.3 | BA47: 126 | BB47: 136 | BC47: 136 | BD47: 0
A48: 28 | B48: Phoenix | C48: J SERIES | D48: Mercury phones | E48: Russia | F48: Done | G48: 136 | H48: 1.0285714 | I48: Superhero | J48: 1 | K48: 1 | L48: 1 | M48: 0 | N48: 1 | O48: 1 | P48: 2 | Q48: 0 | R48: 1 | S48: 2 | T48: 1 | U48: 1 | V48: 3 | W48: 2 | X48: 1 | Y48: 2 | Z48: 1 | AA48: 0 | AB48: 1 | AC48: 0 | AD48: 1 | AE48: 1 | AF48: 3 | AG48: 1 | AH48: 1 | AI48: 1 | AJ48: 0 | AK48: 0 | AL48: 1 | AM48: 1 | AN48: 1 | AO48: 1 | AP48: 1 | AQ48: 0 | AR48: 1 | AS48: Eric Fleischmann | AT48: Andrey Khudenkikh | AU48: Andrey Khudenkikh | AV48: James Erskine | AW48: Bob Fizzard | AX48: Jarek Kovak | AY48: 43586 | AZ48: 8.3 | BA48: 126 | BB48: 136 | BC48: 136 | BD48: 0
A49: 30 | B49: Unicorn | C49: J SERIES | D49: J189 / J189 UI components | E49: Russia | F49: Done | G49: 134 | H49: 0.97142857 | I49: Hero | J49: 1 | K49: 1 | L49: 1 | M49: 0 | N49: 1 | O49: 1 | P49: 2 | Q49: 0 | R49: 1 | S49: 1 | T49: 1 | U49: 1 | V49: 2 | W49: 2 | X49: 1 | Y49: 2 | Z49: 2 | AA49: 1 | AB49: 1 | AC49: 0 | AD49: 1 | AE49: 1 | AF49: 3 | AG49: 1 | AH49: 1 | AI49: 0 | AJ49: 0 | AK49: 0 | AL49: 1 | AM49: 1 | AN49: 1 | AO49: 0 | AP49: 1 | AQ49: 0 | AR49: 1 | AS49: Eric Fleischmann | AT49: Svetlana Podogova | AU49: Stephane Lefebvre | AV49: James Erskine | AW49: Bob Fizzard | AX49: Jarek Kovak | AY49: 43586 | AZ49: 8.3 | BA49: 126 | BB49: 134 | BC49: 134 | BD49: 0
A50: 32 | B50: Wyvern | C50: J SERIES | D50: LDAP, IPv6 | E50: Russia | F50: Done | G50: 134 | H50: 0.97142857 | I50: Hero | J50: 1 | K50: 1 | L50: 1 | M50: 0 | N50: 1 | O50: 1 | P50: 2 | Q50: 0 | R50: 1 | S50: 2 | T50: 1 | U50: 1 | V50: 2 | W50: 2 | X50: 1 | Y50: 1 | Z50: 1 | AA50: 1 | AB50: 1 | AC50: 0 | AD50: 1 | AE50: 1 | AF50: 3 | AG50: 1 | AH50: 1 | AI50: 0 | AJ50: 1 | AK50: 0 | AL50: 1 | AM50: 1 | AN50: 0 | AO50: 1 | AP50: 1 | AQ50: 0 | AR50: 1 | AS50: Eric Fleischmann | AT50: Alex Lyubimov | AU50: Nina Yunusova, Paul Haig, Brian Pick | AV50: James Erskine | AW50: Bob Fizzard | AX50: Jarek Kovak | AY50: 43586 | AZ50: 8.3 | BA50: 126 | BB50: 134 | BC50: 134 | BD50: 0
A51: 36 | B51: Black Pearl | C51: J SERIES | E51: India | F51: Done | G51: 129 | H51: 0.82857143 | I51: Hero | J51: 1 | K51: 1 | L51: 1 | M51: 0 | N51: 1 | O51: 2 | P51: 1 | Q51: 1 | R51: 0 | S51: 0 | T51: 0 | U51: 1 | V51: 3 | W51: 1 | X51: 1 | Y51: 1 | Z51: 1 | AA51: 1 | AB51: 1 | AC51: 0 | AD51: 1 | AE51: 1 | AF51: 3 | AG51: 1 | AH51: 1 | AI51: 0 | AJ51: 0 | AK51: 0 | AL51: 0 | AM51: 1 | AN51: 1 | AO51: 1 | AP51: 0 | AQ51: 0 | AR51: 1 | AS51: Vijay Bholwani | AT51: Gyanesh Soni | AV51: James Erskine | AW51: Bob Fizzard | AX51: Jarek Kovak | AY51: 43586 | AZ51: 8.3 | BA51: 120 | BB51: 129 | BC51: 129 | BD51: 0
A52: 39 | B52: Hakuna Matata | C52: Vantage | D52: Services | E52: Israel | F52: Done | G52: 128 | H52: 0.8 | I52: Hero | J52: 1 | K52: 1 | L52: 2 | M52: 0 | N52: 1 | O52: 1 | P52: 2 | Q52: 2 | R52: 1 | S52: 2 | T52: 0 | U52: 0 | V52: 3 | W52: 1 | X52: 1 | Y52: 1 | Z52: 0 | AA52: 0 | AB52: 0 | AC52: 0 | AD52: 0 | AE52: 1 | AF52: 0 | AG52: 0 | AH52: 2 | AI52: 1 | AJ52: 0 | AK52: 0 | AL52: 0 | AM52: 1 | AN52: 0 | AO52: 3 | AP52: 1 | AQ52: 0 | AR52: 0 | AS52: Erez Morabia | AT52: Victoria Lutsenko | AU52: Ronen Bar-Yoav | AV52: Yuval Cohen | AW52: Vandana Brar | AX52: Jarek Kovak | AY52: 43586 | AZ52: 8.3 | BA52: 128 | BB52: 127 | BC52: 128 | BD52: 1
A53: 42 | B53: Warriors | C53: Vantage | D53: Platform | E53: Israel | F53: Done | G53: 125 | H53: 0.71428571 | I53: Hero | J53: 1 | K53: 1 | L53: 2 | M53: 0 | N53: 0 | O53: 0 | P53: 2 | Q53: 2 | R53: 1 | S53: 2 | T53: 1 | U53: 0 | V53: 2 | W53: 1 | X53: 1 | Y53: 1 | Z53: 0 | AA53: 0 | AB53: 0 | AC53: 0 | AD53: 0 | AE53: 1 | AF53: 0 | AG53: 0 | AH53: 1 | AI53: 1 | AJ53: 0 | AK53: 0 | AL53: 0 | AM53: 1 | AN53: 0 | AO53: 3 | AP53: 1 | AQ53: 0 | AR53: 0 | AS53: Erez Morabia | AT53: Alex Krichevsky | AU53: Ronen Bar-Yoav | AV53: Yuval Cohen | AW53: Vandana Brar | AX53: Jarek Kovak | AY53: 43586 | AZ53: 8.3 | BA53: 127 | BB53: 125 | BC53: 125 | BD53: 0
A54: 50 | B54: Lollipop | C54: Vantage | D54: Connect | E54: Israel | F54: Done | G54: 119 | H54: 0.54285714 | I54: Hero | J54: 1 | K54: 1 | L54: 2 | M54: 0 | N54: 0 | O54: 0 | P54: 1 | Q54: 0 | R54: 1 | S54: 2 | T54: 0 | U54: 0 | V54: 2 | W54: 1 | X54: 1 | Y54: 0 | Z54: 0 | AA54: 0 | AB54: 0 | AC54: 0 | AD54: 0 | AE54: 1 | AF54: 0 | AG54: 0 | AH54: 1 | AI54: 1 | AJ54: 0 | AK54: 0 | AL54: 0 | AM54: 0 | AN54: 0 | AO54: 3 | AP54: 1 | AQ54: 0 | AR54: 0 | AS54: Erez Morabia | AT54: Alex Borodin | AU54: Tair Sasson | AV54: Yuval Cohen | AW54: Vandana Brar | AX54: Jarek Kovak | AY54: 43586 | AZ54: 8.3 | BA54: 123 | BB54: 118 | BC54: 119 | BD54: 1
A55: 52 | B55: Arya | C55: Vantage | D55: Audio | E55: India | F55: Done | G55: 118 | H55: 0.51428571 | I55: Hero | J55: 1 | K55: 1 | L55: 1 | M55: 0 | N55: 0 | O55: 0 | P55: 2 | Q55: 0 | R55: 1 | S55: 2 | T55: 0 | U55: 0 | V55: 2 | W55: 2 | X55: 1 | Y55: 0 | Z55: 0 | AA55: 0 | AB55: 0 | AC55: 0 | AD55: 0 | AE55: 1 | AF55: 0 | AG55: 0 | AH55: 1 | AI55: 0 | AJ55: 0 | AK55: 0 | AL55: 0 | AM55: 1 | AN55: 0 | AO55: 2 | AP55: 0 | AQ55: 0 | AR55: 0 | AS55: Vijay Bholwani | AT55: Sumita Divakaran | AU55: Ronen Bar-Yoav | AV55: Yuval Cohen | AW55: Vandana Brar | AX55: Jarek Kovak | AY55: 43586 | AZ55: 8.3 | BA55: 122 | BB55: 118 | BC55: 118 | BD55: 0
A56: 53 | B56: Vantage Platform | C56: Vantage | D56: Platform | E56: Russia | F56: Done | G56: 112 | H56: 0.34285714 | I56: Hero | J56: 1 | K56: 0 | L56: 0 | M56: 1 | N56: 0 | O56: 0 | P56: 0 | Q56: 0 | R56: 0 | S56: 0 | T56: 0 | U56: 0 | V56: 0 | W56: 0 | X56: 2 | Y56: 0 | Z56: 0 | AA56: 1 | AB56: 1 | AC56: 0 | AD56: 0 | AE56: 1 | AF56: 0 | AG56: 0 | AH56: 1 | AI56: 0 | AJ56: 0 | AK56: 0 | AL56: 0 | AM56: 0 | AN56: 0 | AO56: 3 | AP56: 1 | AQ56: 0 | AR56: 0 | AS56: Erez Morabia | AT56: NA | AU56: Ronen Bar-Yoav | AV56: Yuval Cohen | AW56: Vandana Brar | AX56: Jarek Kovak | AY56: 43586 | AZ56: 8.3 | BA56: 0 | BB56: 112 | BC56: 112 | BD56: 0

Sheet by Product & AIM Area
A1: AIM Area | B1: Aim Category | C1: ACM | D1: AADS | E1: ACI | F1: AES | G1: Analytics 3.x | H1: Analytics 4.0 | I1: ASBCE | J1: AWFOS | K1: CBA | L1: CM | M1: Conf EPs | N1: Connect | O1: DES | P1: Equinox Management | Q1: IX OneSpace | R1: IX Workplace Client | S1: IX-CC | T1: J SERIES | U1: Oceana Core | V1: PLATFORMS | W1: POM | X1: Skype for Business | Y1: SM | Z1: SMGR | AA1: Survey Assist | AB1: Usage Metering | AC1: Vantage | AD1: Category average
A2: Team Structure | B2: Product Owner | C2: =SUMPRODUCT((Original!$C$3:$C$58='by Product & AIM Area'!C$1)*(Original!$O$2:$AW$2='by Product & AIM Area'!$B2)*(Original!$O$3:$AW$58)) / SUMPRODUCT((Original!$C$3:$C$58='by Product & AIM Area'!C$1)*(Original!$J$2:$AW$2='by Product & AIM Area'!$B2)) -> 2 | D2: =SUMPRODUCT((Original!$C$3:$C$58='by Product & AIM Area'!D$1)*(Original!$O$2:$AW$2='by Product & AIM Area'!$B2)*(Original!$O$3:$AW$58)) / SUMPRODUCT((Original!$C$3:$C$58='by Product & AIM Area'!D$1)*(Original!$J$2:$AW$2='by Product & AIM Area'!$B2)) -> 1 | E2: =SUMPRODUCT((Original!$C$3:$C$58='by Product & AIM Area'!E$1)*(Original!$O$2:$AW$2='by Product & AIM Area'!$B2)*(Original!$O$3:$AW$58)) / SUMPRODUCT((Original!$C$3:$C$58='by Product & AIM Area'!E$1)*(Original!$J$2:$AW$2='by Product & AIM Area'!$B2)) -> 1 | F2: =SUMPRODUCT((Original!$C$3:$C$58='by Product & AIM Area'!F$1)*(Original!$O$2:$AW$2='by Product & AIM Area'!$B2)*(Original!$O$3:$AW$58)) / SUMPRODUCT((Original!$C$3:$C$58='by Product & AIM Area'!F$1)*(Original!$J$2:$AW$2='by Product & AIM Area'!$B2)) -> #DIV/0! | G2: =SUMPRODUCT((Original!$C$3:$C$58='by Product & AIM Area'!G$1)*(Original!$O$2:$AW$2='by Product & AIM Area'!$B2)*(Original!$O$3:$AW$58)) / SUMPRODUCT((Original!$C$3:$C$58='by Product & AIM Area'!G$1)*(Original!$J$2:$AW$2='by Product & AIM Area'!$B2)) -> #DIV/0! | H2: =SUMPRODUCT((Original!$C$3:$C$58='by Product & AIM Area'!H$1)*(Original!$O$2:$AW$2='by Product & AIM Area'!$B2)*(Original!$O$3:$AW$58)) / SUMPRODUCT((Original!$C$3:$C$58='by Product & AIM Area'!H$1)*(Original!$J$2:$AW$2='by Product & AIM Area'!$B2)) -> #DIV/0! | I2: =SUMPRODUCT((Original!$C$3:$C$58='by Product & AIM Area'!I$1)*(Original!$O$2:$AW$2='by Product & AIM Area'!$B2)*(Original!$O$3:$AW$58)) / SUMPRODUCT((Original!$C$3:$C$58='by Product & AIM Area'!I$1)*(Original!$J$2:$AW$2='by Product & AIM Area'!$B2)) -> 1 | J2: =SUMPRODUCT((Original!$C$3:$C$58='by Product & AIM Area'!J$1)*(Original!$O$2:$AW$2='by Product & AIM Area'!$B2)*(Original!$O$3:$AW$58)) / SUMPRODUCT((Original!$C$3:$C$58='by Product & AIM Area'!J$1)*(Original!$J$2:$AW$2='by Product & AIM Area'!$B2)) -> 1 | ... AC2: =SUMPRODUCT((Original!$C$3:$C$58='by Product & AIM Area'!AC$1)*(Original!$O$2:$AW$2='by Product & AIM Area'!$B2)*(Original!$O$3:$AW$58)) / SUMPRODUCT((Original!$C$3:$C$58='by Product & AIM Area'!AC$1)*(Original!$J$2:$AW$2='by Product & AIM Area'!$B2)) -> 1 | AD2: =AVERAGE(C2:AC2) -> #DIV/0!
A3: Team Structure | B3: Scrum Master | C3: =SUMPRODUCT((Original!$C$3:$C$58='by Product & AIM Area'!C$1)*(Original!$O$2:$AW$2='by Product & AIM Area'!$B3)*(Original!$O$3:$AW$58)) / SUMPRODUCT((Original!$C$3:$C$58='by Product & AIM Area'!C$1)*(Original!$J$2:$AW$2='by Product & AIM Area'!$B3)) -> 2 | D3: =SUMPRODUCT((Original!$C$3:$C$58='by Product & AIM Area'!D$1)*(Original!$O$2:$AW$2='by Product & AIM Area'!$B3)*(Original!$O$3:$AW$58)) / SUMPRODUCT((Original!$C$3:$C$58='by Product & AIM Area'!D$1)*(Original!$J$2:$AW$2='by Product & AIM Area'!$B3)) -> 1 | E3: =SUMPRODUCT((Original!$C$3:$C$58='by Product & AIM Area'!E$1)*(Original!$O$2:$AW$2='by Product & AIM Area'!$B3)*(Original!$O$3:$AW$58)) / SUMPRODUCT((Original!$C$3:$C$58='by Product & AIM Area'!E$1)*(Original!$J$2:$AW$2='by Product & AIM Area'!$B3)) -> 1 | F3: =SUMPRODUCT((Original!$C$3:$C$58='by Product & AIM Area'!F$1)*(Original!$O$2:$AW$2='by Product & AIM Area'!$B3)*(Original!$O$3:$AW$58)) / SUMPRODUCT((Original!$C$3:$C$58='by Product & AIM Area'!F$1)*(Original!$J$2:$AW$2='by Product & AIM Area'!$B3)) -> #DIV/0! | G3: =SUMPRODUCT((Original!$C$3:$C$58='by Product & AIM Area'!G$1)*(Original!$O$2:$AW$2='by Product & AIM Area'!$B3)*(Original!$O$3:$AW$58)) / SUMPRODUCT((Original!$C$3:$C$58='by Product & AIM Area'!G$1)*(Original!$J$2:$AW$2='by Product & AIM Area'!$B3)) -> #DIV/0! | H3: =SUMPRODUCT((Original!$C$3:$C$58='by Product & AIM Area'!H$1)*(Original!$O$2:$AW$2='by Product & AIM Area'!$B3)*(Original!$O$3:$AW$58)) / SUMPRODUCT((Original!$C$3:$C$58='by Product & AIM Area'!H$1)*(Original!$J$2:$AW$2='by Product & AIM Area'!$B3)) -> #DIV/0! | I3: =SUMPRODUCT((Original!$C$3:$C$58='by Product & AIM Area'!I$1)*(Original!$O$2:$AW$2='by Product & AIM Area'!$B3)*(Original!$O$3:$AW$58)) / SUMPRODUCT((Original!$C$3:$C$58='by Product & AIM Area'!I$1)*(Original!$J$2:$AW$2='by Product & AIM Area'!$B3)) -> 1 | J3: =SUMPRODUCT((Original!$C$3:$C$58='by Product & AIM Area'!J$1)*(Original!$O$2:$AW$2='by Product & AIM Area'!$B3)*(Original!$O$3:$AW$58)) / SUMPRODUCT((Original!$C$3:$C$58='by Product & AIM Area'!J$1)*(Original!$J$2:$AW$2='by Product & AIM Area'!$B3)) -> 1 | ... AC3: =SUMPRODUCT((Original!$C$3:$C$58='by Product & AIM Area'!AC$1)*(Original!$O$2:$AW$2='by Product & AIM Area'!$B3)*(Original!$O$3:$AW$58)) / SUMPRODUCT((Original!$C$3:$C$58='by Product & AIM Area'!AC$1)*(Original!$J$2:$AW$2='by Product & AIM Area'!$B3)) -> 0.8 | AD3: =AVERAGE(C3:AC3) -> #DIV/0!
